File: training_data/P01_Test003Data.csv
SetName,Cycle,Time_S,Size_mm,Displacement_mm,Force_N,Stretch,Stress [kPa],Disp,,,,,,,,,,Area [mm2]
Load 1,1-Compress,0,4.37,0,0.385,1,4.901972247,0,,,,,,,,,,78.53981634
Load 1,1-Compress,16,4.353,0.017,0.385,0.99610984,4.901972247,0.017,,,,,,,,,,
Load 1,1-Compress,32,4.338,0.032,0.385,0.992677346,4.901972247,0.032,,,,,,,,,,
Load 1,1-Compress,48,4.321,0.049,0.385,0.988787185,4.901972247,0.049,,,,,,,,,,
Load 1,1-Compress,64,4.305,0.065,0.685,0.985125858,8.721690881,0.065,,,,,,,,,,
Load 1,1-Compress,80,4.289,0.081,0.685,0.981464531,8.721690881,0.081,,,,,,,,,,
Load 1,1-Compress,96,4.273,0.097,0.685,0.977803204,8.721690881,0.097,,,,,,,,,,
Load 1,1-Compress,112,4.257,0.113,0.885,0.974141876,11.26816997,0.113,,,,,,,,,,
Load 1,1-Compress,128,4.241,0.129,0.985,0.970480549,12.54140952,0.129,,,,,,,,,,
Load 1,1-Compress,144,4.225,0.145,0.985,0.966819222,12.54140952,0.145,,,,,,,,,,
Load 1,1-Compress,160,4.209,0.161,1.185,0.963157895,15.08788861,0.161,,,,,,,,,,
Load 1,1-Compress,176,4.193,0.177,1.085,0.959496568,13.81464906,0.177,,,,,,,,,,
Load 1,1-Compress,192,4.177,0.193,1.385,0.95583524,17.63436769,0.193,,,,,,,,,,
Load 1,1-Compress,208,4.161,0.209,1.485,0.952173913,18.90760724,0.209,,,,,,,,,,
Load 1,1-Compress,224,4.145,0.225,1.685,0.948512586,21.45408633,0.225,,,,,,,,,,
Load 1,1-Compress,240,4.129,0.241,1.985,0.944851259,25.27380496,0.241,,,,,,,,,,
Load 1,1-Compress,256,4.113,0.257,1.885,0.941189931,24.00056542,0.257,,,,,,,,,,
Load 1,1-Compress,272,4.097,0.273,2.285,0.937528604,29.0935236,0.273,,,,,,,,,,
Load 1,1-Compress,288,4.081,0.289,2.285,0.933867277,29.0935236,0.289,,,,,,,,,,
Load 1,1-Compress,304,4.066,0.304,2.285,0.930434783,29.0935236,0.304,,,,,,,,,,
Load 1,1-Compress,320,4.05,0.32,2.085,0.926773455,26.54704451,0.32,,,,,,,,,,
Load 1,1-Compress,336,4.033,0.337,2.385,0.922883295,30.36676314,0.337,,,,,,,,,,
Load 1,1-Compress,352,4.017,0.353,2.785,0.919221968,35.45972132,0.353,,,,,,,,,,
Load 1,1-Compress,368,4.002,0.368,2.685,0.915789474,34.18648178,0.368,,,,,,,,,,
Load 1,1-Compress,384,3.986,0.384,2.985,0.912128146,38.00620041,0.384,,,,,,,,,,
Load 1,1-Compress,400,3.969,0.401,3.085,0.908237986,39.27943995,0.401,,,,,,,,,,
Load 1,1-Compress,416,3.953,0.417,3.385,0.904576659,43.09915859,0.417,,,,,,,,,,
Load 1,1-Compress,432,3.937,0.433,3.985,0.900915332,50.73859586,0.433,,,,,,,,,,
Load 1,1-Hold,447.3,3.933,0.437,2.385,0.9,30.36676314,0.437,,,,,,,,,,
Load 1,1-Hold,463.3,3.933,0.437,2.285,0.9,29.0935236,0.437,,,,,,,,,,
Load 1,1-Hold,479.3,3.933,0.437,1.985,0.9,25.27380496,0.437,,,,,,,,,,
Load 1,1-Hold,495.3,3.933,0.437,1.585,0.9,20.18084678,0.437,,,,,,,,,,
Load 1,1-Hold,511.3,3.933,0.437,1.585,0.9,20.18084678,0.437,,,,,,,,,,
Load 1,1-Hold,527.3,3.933,0.437,1.485,0.9,18.90760724,0.437,,,,,,,,,,
Load 1,1-Hold,543.3,3.933,0.437,1.285,0.9,16.36112815,0.437,,,,,,,,,,
Load 1,1-Hold,559.3,3.933,0.437,1.185,0.9,15.08788861,0.437,,,,,,,,,,
Load 1,1-Hold,575.3,3.933,0.437,1.185,0.9,15.08788861,0.437,,,,,,,,,,
Load 1,1-Hold,591.3,3.933,0.437,1.185,0.9,15.08788861,0.437,,,,,,,,,,
Load 1,1-Hold,607.3,3.933,0.437,1.185,0.9,15.08788861,0.437,,,,,,,,,,
Load 1,1-Hold,623.3,3.933,0.437,0.785,0.9,9.994930426,0.437,,,,,,,,,,
Load 1,1-Hold,639.3,3.933,0.437,0.785,0.9,9.994930426,0.437,,,,,,,,,,
Load 1,1-Hold,655.3,3.933,0.437,0.785,0.9,9.994930426,0.437,,,,,,,,,,
Load 1,1-Hold,671.3,3.933,0.437,0.785,0.9,9.994930426,0.437,,,,,,,,,,
Load 1,1-Hold,687.3,3.933,0.437,0.785,0.9,9.994930426,0.437,,,,,,,,,,
Load 1,1-Hold,703.3,3.933,0.437,0.785,0.9,9.994930426,0.437,,,,,,,,,,
Load 1,1-Hold,719.3,3.933,0.437,0.785,0.9,9.994930426,0.437,,,,,,,,,,
Load 1,1-Hold,735.3,3.933,0.437,0.485,0.9,6.175211792,0.437,,,,,,,,,,
Load 1,1-Hold,751.3,3.933,0.437,0.685,0.9,8.721690881,0.437,,,,,,,,,,
Load 1,1-Hold,767.3,3.933,0.437,-1.015,0.9,-12.92338138,0.437,,,,,,,,,,
Load 1,1-Hold,783.3,3.933,0.437,-0.815,0.9,-10.37690229,0.437,,,,,,,,,,
Load 1,1-Hold,799.3,3.933,0.437,-0.815,0.9,-10.37690229,0.437,,,,,,,,,,
Load 1,1-Hold,815.3,3.933,0.437,-0.815,0.9,-10.37690229,0.437,,,,,,,,,,
Load 1,1-Hold,831.3,3.933,0.437,-0.815,0.9,-10.37690229,0.437,,,,,,,,,,
Load 1,1-Hold,847.3,3.933,0.437,-0.415,0.9,-5.283944111,0.437,,,,,,,,,,
Load 1,1-Hold,863.3,3.933,0.437,-0.715,0.9,-9.103662745,0.437,,,,,,,,,,
Load 1,1-Hold,879.3,3.933,0.437,-0.415,0.9,-5.283944111,0.437,,,,,,,,,,
Load 1,1-Hold,895.3,3.933,0.437,-0.415,0.9,-5.283944111,0.437,,,,,,,,,,
Load 1,1-Hold,911.3,3.933,0.437,-0.415,0.9,-5.283944111,0.437,,,,,,,,,,
Load 1,1-Hold,927.3,3.933,0.437,-0.415,0.9,-5.283944111,0.437,,,,,,,,,,
Load 2,1-Compress,942.62,3.927,0.006,1.185,0.898627002,15.08788861,0.443,,,,,,,,,,
Load 2,1-Compress,958.62,3.911,0.022,1.585,0.894965675,20.18084678,0.459,,,,,,,,,,
Load 2,1-Compress,974.62,3.895,0.038,2.185,0.891304348,27.82028405,0.475,,,,,,,,,,
Load 2,1-Compress,990.62,3.879,0.054,2.585,0.887643021,32.91324223,0.491,,,,,,,,,,
Load 2,1-Compress,1006.62,3.863,0.07,3.385,0.883981693,43.09915859,0.507,,,,,,,,,,
Load 2,1-Compress,1022.62,3.847,0.086,4.185,0.880320366,53.28507495,0.523,,,,,,,,,,
Load 2,1-Compress,1038.62,3.831,0.102,4.385,0.876659039,55.83155404,0.539,,,,,,,,,,
Load 2,1-Compress,1054.62,3.815,0.118,4.885,0.872997712,62.19775176,0.555,,,,,,,,,,
Load 2,1-Compress,1070.62,3.799,0.134,5.286,0.869336384,67.30344233,0.571,,,,,,,,,,
Load 2,1-Compress,1086.62,3.783,0.15,5.986,0.865675057,76.21611915,0.587,,,,,,,,,,
Load 2,1-Compress,1102.62,3.767,0.166,6.386,0.86201373,81.30907733,0.603,,,,,,,,,,
Load 2,1-Compress,1118.62,3.751,0.182,6.786,0.858352403,86.40203551,0.619,,,,,,,,,,
Load 2,1-Compress,1134.62,3.736,0.197,7.186,0.854919908,91.49499368,0.634,,,,,,,,,,
Load 2,1-Compress,1150.62,3.719,0.214,7.986,0.851029748,101.68091,0.651,,,,,,,,,,
Load 2,1-Compress,1166.62,3.703,0.23,8.286,0.847368421,105.5006287,0.667,,,,,,,,,,
Load 2,1-Compress,1182.62,3.687,0.246,8.686,0.843707094,110.5935869,0.683,,,,,,,,,,
Load 2,1-Compress,1198.62,3.672,0.261,9.186,0.8402746,116.9597846,0.698,,,,,,,,,,
Load 2,1-Compress,1214.62,3.656,0.277,9.986,0.836613272,127.1457009,0.714,,,,,,,,,,
Load 2,1-Compress,1230.62,3.64,0.293,10.286,0.832951945,130.9654196,0.73,,,,,,,,,,
Load 2,1-Compress,1246.62,3.623,0.31,10.786,0.829061785,137.3316173,0.747,,,,,,,,,,
Load 2,1-Compress,1262.62,3.607,0.326,11.486,0.825400458,146.2442941,0.763,,,,,,,,,,
Load 2,1-Compress,1278.62,3.591,0.342,11.886,0.82173913,151.3372523,0.779,,,,,,,,,,
Load 2,1-Compress,1294.62,3.575,0.358,12.386,0.818077803,157.70345,0.795,,,,,,,,,,
Load 2,1-Compress,1310.62,3.56,0.373,12.786,0.814645309,162.7964082,0.81,,,,,,,,,,
Load 2,1-Compress,1326.62,3.544,0.389,13.186,0.810983982,167.8893664,0.826,,,,,,,,,,
Load 2,1-Compress,1342.62,3.527,0.406,14.686,0.807093822,186.9879595,0.843,,,,,,,,,,
Load 2,1-Compress,1358.62,3.511,0.422,14.986,0.803432494,190.8076782,0.859,,,,,,,,,,
Load 2,1-Compress,1374.62,3.496,0.437,14.586,0.8,185.71472,0.874,,,,,,,,,,
Load 2,1-Hold,1389.91,3.496,0.437,11.586,0.8,147.5175337,0.874,,,,,,,,,,
Load 2,1-Hold,1405.91,3.496,0.437,9.986,0.8,127.1457009,0.874,,,,,,,,,,
Load 2,1-Hold,1421.91,3.496,0.437,9.186,0.8,116.9597846,0.874,,,,,,,,,,
Load 2,1-Hold,1437.91,3.496,0.437,8.286,0.8,105.5006287,0.874,,,,,,,,,,
Load 2,1-Hold,1453.91,3.496,0.437,7.686,0.8,97.86119141,0.874,,,,,,,,,,
Load 2,1-Hold,1469.91,3.496,0.437,6.986,0.8,88.94851459,0.874,,,,,,,,,,
Load 2,1-Hold,1485.91,3.496,0.437,6.786,0.8,86.40203551,0.874,,,,,,,,,,
Load 2,1-Hold,1501.91,3.496,0.437,6.186,0.8,78.76259824,0.874,,,,,,,,,,
Load 2,1-Hold,1517.91,3.496,0.437,6.086,0.8,77.48935869,0.874,,,,,,,,,,
Load 2,1-Hold,1533.91,3.496,0.437,5.986,0.8,76.21611915,0.874,,,,,,,,,,
Load 2,1-Hold,1549.91,3.496,0.437,5.986,0.8,76.21611915,0.874,,,,,,,,,,
Load 2,1-Hold,1565.91,3.496,0.437,5.886,0.8,74.9428796,0.874,,,,,,,,,,
Load 2,1-Hold,1581.91,3.496,0.437,5.186,0.8,66.03020279,0.874,,,,,,,,,,
Load 2,1-Hold,1597.91,3.496,0.437,5.186,0.8,66.03020279,0.874,,,,,,,,,,
Load 2,1-Hold,1613.91,3.496,0.437,5.186,0.8,66.03020279,0.874,,,,,,,,,,
Load 2,1-Hold,1629.91,3.496,0.437,5.186,0.8,66.03020279,0.874,,,,,,,,,,
Load 2,1-Hold,1645.91,3.496,0.437,5.086,0.8,64.75696325,0.874,,,,,,,,,,
Load 2,1-Hold,1661.91,3.496,0.437,5.086,0.8,64.75696325,0.874,,,,,,,,,,
Load 2,1-Hold,1677.91,3.496,0.437,4.785,0.8,60.92451222,0.874,,,,,,,,,,
Load 2,1-Hold,1693.91,3.496,0.437,4.285,0.8,54.55831449,0.874,,,,,,,,,,
Load 2,1-Hold,1709.91,3.496,0.437,4.185,0.8,53.28507495,0.874,,,,,,,,,,
Load 2,1-Hold,1725.91,3.496,0.437,4.285,0.8,54.55831449,0.874,,,,,,,,,,
Load 2,1-Hold,1741.91,3.496,0.437,3.685,0.8,46.91887722,0.874,,,,,,,,,,
Load 2,1-Hold,1757.91,3.496,0.437,3.685,0.8,46.91887722,0.874,,,,,,,,,,
Load 2,1-Hold,1773.91,3.496,0.437,3.685,0.8,46.91887722,0.874,,,,,,,,,,
Load 2,1-Hold,1789.91,3.496,0.437,3.885,0.8,49.46535631,0.874,,,,,,,,,,
Load 2,1-Hold,1805.91,3.496,0.437,3.785,0.8,48.19211677,0.874,,,,,,,,,,
Load 2,1-Hold,1821.91,3.496,0.437,3.785,0.8,48.19211677,0.874,,,,,,,,,,
Load 2,1-Hold,1837.91,3.496,0.437,3.585,0.8,45.64563768,0.874,,,,,,,,,,
Load 2,1-Hold,1853.91,3.496,0.437,3.785,0.8,48.19211677,0.874,,,,,,,,,,
Load 2,1-Hold,1869.91,3.496,0.437,3.685,0.8,46.91887722,0.874,,,,,,,,,,
Load 2,1-Hold,1885.91,3.496,0.437,3.685,0.8,46.91887722,0.874,,,,,,,,,,
Load 2,1-Hold,1901.91,3.496,0.437,3.685,0.8,46.91887722,0.874,,,,,,,,,,
Load 2,1-Hold,1917.91,3.496,0.437,3.685,0.8,46.91887722,0.874,,,,,,,,,,
Load 2,1-Hold,1933.91,3.496,0.437,3.585,0.8,45.64563768,0.874,,,,,,,,,,
Load 2,1-Hold,1949.91,3.496,0.437,3.585,0.8,45.64563768,0.874,,,,,,,,,,
Load 2,1-Hold,1965.91,3.496,0.437,3.585,0.8,45.64563768,0.874,,,,,,,,,,
Load 2,1-Hold,1981.91,3.496,0.437,3.485,0.8,44.37239813,0.874,,,,,,,,,,
Load 2,1-Hold,1997.91,3.496,0.437,3.185,0.8,40.5526795,0.874,,,,,,,,,,
Load 2,1-Hold,2013.91,3.496,0.437,2.985,0.8,38.00620041,0.874,,,,,,,,,,
Load 2,1-Hold,2029.91,3.496,0.437,2.985,0.8,38.00620041,0.874,,,,,,,,,,
Load 2,1-Hold,2045.91,3.496,0.437,2.985,0.8,38.00620041,0.874,,,,,,,,,,
Load 2,1-Hold,2061.91,3.496,0.437,2.985,0.8,38.00620041,0.874,,,,,,,,,,
Load 2,1-Hold,2077.91,3.496,0.437,2.985,0.8,38.00620041,0.874,,,,,,,,,,
Load 2,1-Hold,2093.91,3.496,0.437,2.985,0.8,38.00620041,0.874,,,,,,,,,,
Load 2,1-Hold,2109.91,3.496,0.437,2.985,0.8,38.00620041,0.874,,,,,,,,,,
Load 2,1-Hold,2125.91,3.496,0.437,2.985,0.8,38.00620041,0.874,,,,,,,,,,
Load 2,1-Hold,2141.91,3.496,0.437,2.985,0.8,38.00620041,0.874,,,,,,,,,,
Load 2,1-Hold,2157.91,3.496,0.437,2.985,0.8,38.00620041,0.874,,,,,,,,,,
Load 2,1-Hold,2173.91,3.496,0.437,2.885,0.8,36.73296087,0.874,,,,,,,,,,
Load 2,1-Hold,2189.91,3.496,0.437,2.985,0.8,38.00620041,0.874,,,,,,,,,,
Load 2,1-Hold,2205.91,3.496,0.437,2.985,0.8,38.00620041,0.874,,,,,,,,,,
Load 2,1-Hold,2221.91,3.496,0.437,2.985,0.8,38.00620041,0.874,,,,,,,,,,
Load 2,1-Hold,2237.91,3.496,0.437,2.985,0.8,38.00620041,0.874,,,,,,,,,,
Load 2,1-Hold,2253.91,3.496,0.437,2.985,0.8,38.00620041,0.874,,,,,,,,,,
Load 2,1-Hold,2269.91,3.496,0.437,2.985,0.8,38.00620041,0.874,,,,,,,,,,
Load 2,1-Hold,2285.91,3.496,0.437,2.985,0.8,38.00620041,0.874,,,,,,,,,,
Load 2,1-Hold,2301.91,3.496,0.437,2.985,0.8,38.00620041,0.874,,,,,,,,,,
Load 2,1-Hold,2317.91,3.496,0.437,2.885,0.8,36.73296087,0.874,,,,,,,,,,
Load 2,1-Hold,2333.91,3.496,0.437,2.885,0.8,36.73296087,0.874,,,,,,,,,,
Load 2,1-Hold,2349.91,3.496,0.437,2.785,0.8,35.45972132,0.874,,,,,,,,,,
Load 2,1-Hold,2365.91,3.496,0.437,2.785,0.8,35.45972132,0.874,,,,,,,,,,
Load 2,1-Hold,2381.91,3.496,0.437,2.785,0.8,35.45972132,0.874,,,,,,,,,,
Load 2,1-Hold,2397.91,3.496,0.437,2.785,0.8,35.45972132,0.874,,,,,,,,,,
Load 2,1-Hold,2413.91,3.496,0.437,2.785,0.8,35.45972132,0.874,,,,,,,,,,
Load 2,1-Hold,2429.91,3.496,0.437,2.485,0.8,31.64000269,0.874,,,,,,,,,,
Load 2,1-Hold,2445.91,3.496,0.437,2.185,0.8,27.82028405,0.874,,,,,,,,,,
Load 2,1-Hold,2461.91,3.496,0.437,2.585,0.8,32.91324223,0.874,,,,,,,,,,
Load 2,1-Hold,2477.91,3.496,0.437,2.485,0.8,31.64000269,0.874,,,,,,,,,,
Load 2,1-Hold,2493.91,3.496,0.437,2.785,0.8,35.45972132,0.874,,,,,,,,,,
Load 2,1-Hold,2509.91,3.496,0.437,2.385,0.8,30.36676314,0.874,,,,,,,,,,
Load 2,1-Hold,2525.91,3.496,0.437,2.685,0.8,34.18648178,0.874,,,,,,,,,,
Load 2,1-Hold,2541.91,3.496,0.437,2.785,0.8,35.45972132,0.874,,,,,,,,,,
Load 2,1-Hold,2557.91,3.496,0.437,2.785,0.8,35.45972132,0.874,,,,,,,,,,
Load 2,1-Hold,2573.91,3.496,0.437,2.785,0.8,35.45972132,0.874,,,,,,,,,,
Load 2,1-Hold,2589.91,3.496,0.437,2.785,0.8,35.45972132,0.874,,,,,,,,,,
Load 2,1-Hold,2605.91,3.496,0.437,2.785,0.8,35.45972132,0.874,,,,,,,,,,
Load 2,1-Hold,2621.91,3.496,0.437,2.885,0.8,36.73296087,0.874,,,,,,,,,,
Load 2,1-Hold,2637.91,3.496,0.437,2.785,0.8,35.45972132,0.874,,,,,,,,,,
Load 2,1-Hold,2653.91,3.496,0.437,2.885,0.8,36.73296087,0.874,,,,,,,,,,
Load 2,1-Hold,2669.91,3.496,0.437,2.785,0.8,35.45972132,0.874,,,,,,,,,,
Load 2,1-Hold,2685.91,3.496,0.437,2.785,0.8,35.45972132,0.874,,,,,,,,,,
Load 2,1-Hold,2701.91,3.496,0.437,2.785,0.8,35.45972132,0.874,,,,,,,,,,
Load 2,1-Hold,2717.91,3.496,0.437,2.785,0.8,35.45972132,0.874,,,,,,,,,,
Load 2,1-Hold,2733.91,3.496,0.437,2.785,0.8,35.45972132,0.874,,,,,,,,,,
Load 2,1-Hold,2749.91,3.496,0.437,2.685,0.8,34.18648178,0.874,,,,,,,,,,
Load 2,1-Hold,2765.91,3.496,0.437,2.385,0.8,30.36676314,0.874,,,,,,,,,,
Load 2,1-Hold,2781.91,3.496,0.437,2.385,0.8,30.36676314,0.874,,,,,,,,,,
Load 2,1-Hold,2797.91,3.496,0.437,2.185,0.8,27.82028405,0.874,,,,,,,,,,
Load 2,1-Hold,2813.91,3.496,0.437,2.185,0.8,27.82028405,0.874,,,,,,,,,,
Load 2,1-Hold,2829.91,3.496,0.437,2.185,0.8,27.82028405,0.874,,,,,,,,,,
Load 2,1-Hold,2845.91,3.496,0.437,2.185,0.8,27.82028405,0.874,,,,,,,,,,
Load 2,1-Hold,2861.91,3.496,0.437,2.185,0.8,27.82028405,0.874,,,,,,,,,,
Load 3,1-Compress,2877.9,3.493,0.003,3.685,0.799313501,46.91887722,0.877,,,,,,,,,,
Load 3,1-Compress,2893.9,3.477,0.019,4.685,0.795652174,59.65127267,0.893,,,,,,,,,,
Load 3,1-Compress,2909.9,3.461,0.035,5.886,0.791990847,74.9428796,0.909,,,,,,,,,,
Load 3,1-Compress,2925.9,3.445,0.051,8.086,0.788329519,102.9541496,0.925,,,,,,,,,,
Load 3,1-Compress,2941.9,3.429,0.067,9.586,0.784668192,122.0527428,0.941,,,,,,,,,,
Load 3,1-Compress,2957.9,3.414,0.082,10.786,0.781235698,137.3316173,0.956,,,,,,,,,,
Load 3,1-Compress,2973.9,3.397,0.099,13.186,0.777345538,167.8893664,0.973,,,,,,,,,,
Load 3,1-Compress,2989.9,3.381,0.115,15.487,0.773684211,197.1866083,0.989,,,,,,,,,,
Load 3,1-Compress,3005.9,3.365,0.131,16.187,0.770022883,206.0992851,1.005,,,,,,,,,,
Load 3,1-Compress,3021.9,3.349,0.147,16.787,0.766361556,213.7387224,1.021,,,,,,,,,,
Load 3,1-Compress,3037.9,3.333,0.163,18.187,0.762700229,231.564076,1.037,,,,,,,,,,
Load 3,1-Compress,3053.9,3.317,0.179,19.987,0.759038902,254.4823878,1.053,,,,,,,,,,
Load 3,1-Compress,3069.9,3.301,0.195,20.587,0.755377574,262.1218251,1.069,,,,,,,,,,
Load 3,1-Compress,3085.9,3.285,0.211,21.187,0.751716247,269.7612623,1.085,,,,,,,,,,
Load 3,1-Compress,3101.9,3.269,0.227,21.287,0.74805492,271.0345019,1.101,,,,,,,,,,
Load 3,1-Compress,3117.9,3.253,0.243,22.787,0.744393593,290.1330951,1.117,,,,,,,,,,
Load 3,1-Compress,3133.9,3.237,0.259,23.087,0.740732265,293.9528137,1.133,,,,,,,,,,
Load 3,1-Compress,3149.9,3.221,0.275,23.587,0.737070938,300.3190114,1.149,,,,,,,,,,
Load 3,1-Compress,3165.9,3.206,0.29,23.987,0.733638444,305.4119696,1.164,,,,,,,,,,
Load 3,1-Compress,3181.9,3.19,0.306,24.487,0.729977117,311.7781673,1.18,,,,,,,,,,
Load 3,1-Compress,3197.9,3.173,0.323,24.887,0.726086957,316.8711255,1.197,,,,,,,,,,
Load 3,1-Compress,3213.9,3.157,0.339,24.887,0.722425629,316.8711255,1.213,,,,,,,,,,
Load 3,1-Compress,3229.9,3.141,0.355,25.288,0.718764302,321.9768161,1.229,,,,,,,,,,
Load 3,1-Compress,3245.9,3.125,0.371,26.288,0.715102975,334.7092115,1.245,,,,,,,,,,
Load 3,1-Compress,3261.9,3.109,0.387,26.588,0.711441648,338.5289302,1.261,,,,,,,,,,
Load 3,1-Compress,3277.9,3.093,0.403,25.988,0.70778032,330.8894929,1.277,,,,,,,,,,
Load 3,1-Compress,3293.9,3.077,0.419,26.488,0.704118993,337.2556906,1.293,,,,,,,,,,
Load 3,1-Compress,3309.9,3.061,0.435,27.588,0.700457666,351.2613256,1.309,,,,,,,,,,
Load 3,1-Hold,3325.19,3.059,0.437,22.787,0.7,290.1330951,1.311,,,,,,,,,,
Load 3,1-Hold,3341.19,3.059,0.437,19.587,0.7,249.3894296,1.311,,,,,,,,,,
Load 3,1-Hold,3357.19,3.059,0.437,16.987,0.7,216.2852015,1.311,,,,,,,,,,
Load 3,1-Hold,3373.19,3.059,0.437,14.786,0.7,188.2611991,1.311,,,,,,,,,,
Load 3,1-Hold,3389.19,3.059,0.437,13.486,0.7,171.709085,1.311,,,,,,,,,,
Load 3,1-Hold,3405.19,3.059,0.437,13.186,0.7,167.8893664,1.311,,,,,,,,,,
Load 3,1-Hold,3421.19,3.059,0.437,12.386,0.7,157.70345,1.311,,,,,,,,,,
Load 3,1-Hold,3437.19,3.059,0.437,11.586,0.7,147.5175337,1.311,,,,,,,,,,
Load 3,1-Hold,3453.19,3.059,0.437,10.786,0.7,137.3316173,1.311,,,,,,,,,,
Load 3,1-Hold,3469.19,3.059,0.437,10.086,0.7,128.4189405,1.311,,,,,,,,,,
Load 3,1-Hold,3485.19,3.059,0.437,9.986,0.7,127.1457009,1.311,,,,,,,,,,
Load 3,1-Hold,3501.19,3.059,0.437,9.286,0.7,118.2330241,1.311,,,,,,,,,,
Load 3,1-Hold,3517.19,3.059,0.437,9.986,0.7,127.1457009,1.311,,,,,,,,,,
Load 3,1-Hold,3533.19,3.059,0.437,9.186,0.7,116.9597846,1.311,,,,,,,,,,
Load 3,1-Hold,3549.19,3.059,0.437,9.186,0.7,116.9597846,1.311,,,,,,,,,,
Load 3,1-Hold,3565.19,3.059,0.437,9.086,0.7,115.686545,1.311,,,,,,,,,,
Load 3,1-Hold,3581.19,3.059,0.437,8.386,0.7,106.7738682,1.311,,,,,,,,,,
Load 3,1-Hold,3597.19,3.059,0.437,8.386,0.7,106.7738682,1.311,,,,,,,,,,
Load 3,1-Hold,3613.19,3.059,0.437,8.386,0.7,106.7738682,1.311,,,,,,,,,,
Load 3,1-Hold,3629.19,3.059,0.437,8.286,0.7,105.5006287,1.311,,,,,,,,,,
Load 3,1-Hold,3645.19,3.059,0.437,7.686,0.7,97.86119141,1.311,,,,,,,,,,
Load 3,1-Hold,3661.19,3.059,0.437,7.686,0.7,97.86119141,1.311,,,,,,,,,,
Load 3,1-Hold,3677.19,3.059,0.437,7.686,0.7,97.86119141,1.311,,,,,,,,,,
Load 3,1-Hold,3693.19,3.059,0.437,7.686,0.7,97.86119141,1.311,,,,,,,,,,
Load 3,1-Hold,3709.19,3.059,0.437,7.586,0.7,96.58795186,1.311,,,,,,,,,,
Load 3,1-Hold,3725.19,3.059,0.437,7.586,0.7,96.58795186,1.311,,,,,,,,,,
Load 3,1-Hold,3741.19,3.059,0.437,7.586,0.7,96.58795186,1.311,,,,,,,,,,
Load 3,1-Hold,3757.19,3.059,0.437,7.186,0.7,91.49499368,1.311,,,,,,,,,,
Load 3,1-Hold,3773.19,3.059,0.437,6.986,0.7,88.94851459,1.311,,,,,,,,,,
Load 3,1-Hold,3789.19,3.059,0.437,6.886,0.7,87.67527505,1.311,,,,,,,,,,
Load 3,1-Hold,3805.19,3.059,0.437,6.886,0.7,87.67527505,1.311,,,,,,,,,,
Load 3,1-Hold,3821.19,3.059,0.437,6.886,0.7,87.67527505,1.311,,,,,,,,,,
Load 3,1-Hold,3837.19,3.059,0.437,6.886,0.7,87.67527505,1.311,,,,,,,,,,
Load 3,1-Hold,3853.19,3.059,0.437,6.786,0.7,86.40203551,1.311,,,,,,,,,,
Load 3,1-Hold,3869.19,3.059,0.437,6.786,0.7,86.40203551,1.311,,,,,,,,,,
Load 3,1-Hold,3885.19,3.059,0.437,6.786,0.7,86.40203551,1.311,,,,,,,,,,
Load 3,1-Hold,3901.19,3.059,0.437,6.786,0.7,86.40203551,1.311,,,,,,,,,,
Load 3,1-Hold,3917.19,3.059,0.437,6.186,0.7,78.76259824,1.311,,,,,,,,,,
Load 3,1-Hold,3933.19,3.059,0.437,6.486,0.7,82.58231687,1.311,,,,,,,,,,
Load 3,1-Hold,3949.19,3.059,0.437,6.086,0.7,77.48935869,1.311,,,,,,,,,,
Load 3,1-Hold,3965.19,3.059,0.437,6.186,0.7,78.76259824,1.311,,,,,,,,,,
Load 3,1-Hold,3981.19,3.059,0.437,6.086,0.7,77.48935869,1.311,,,,,,,,,,
Load 3,1-Hold,3997.19,3.059,0.437,6.086,0.7,77.48935869,1.311,,,,,,,,,,
Load 3,1-Hold,4013.19,3.059,0.437,6.086,0.7,77.48935869,1.311,,,,,,,,,,
Load 3,1-Hold,4029.19,3.059,0.437,6.086,0.7,77.48935869,1.311,,,,,,,,,,
Load 3,1-Hold,4045.19,3.059,0.437,6.086,0.7,77.48935869,1.311,,,,,,,,,,
Load 3,1-Hold,4061.19,3.059,0.437,5.986,0.7,76.21611915,1.311,,,,,,,,,,
Load 3,1-Hold,4077.19,3.059,0.437,5.986,0.7,76.21611915,1.311,,,,,,,,,,
Load 3,1-Hold,4093.19,3.059,0.437,5.986,0.7,76.21611915,1.311,,,,,,,,,,
Load 3,1-Hold,4109.19,3.059,0.437,5.986,0.7,76.21611915,1.311,,,,,,,,,,
Load 3,1-Hold,4125.19,3.059,0.437,5.986,0.7,76.21611915,1.311,,,,,,,,,,
Load 3,1-Hold,4141.19,3.059,0.437,5.986,0.7,76.21611915,1.311,,,,,,,,,,
Load 3,1-Hold,4157.19,3.059,0.437,5.986,0.7,76.21611915,1.311,,,,,,,,,,
Load 3,1-Hold,4173.19,3.059,0.437,5.986,0.7,76.21611915,1.311,,,,,,,,,,
Load 3,1-Hold,4189.19,3.059,0.437,6.086,0.7,77.48935869,1.311,,,,,,,,,,
Load 3,1-Hold,4205.19,3.059,0.437,5.986,0.7,76.21611915,1.311,,,,,,,,,,
Load 3,1-Hold,4221.19,3.059,0.437,5.986,0.7,76.21611915,1.311,,,,,,,,,,
Load 3,1-Hold,4237.19,3.059,0.437,5.986,0.7,76.21611915,1.311,,,,,,,,,,
Load 3,1-Hold,4253.19,3.059,0.437,5.986,0.7,76.21611915,1.311,,,,,,,,,,
Load 3,1-Hold,4269.19,3.059,0.437,5.886,0.7,74.9428796,1.311,,,,,,,,,,
Load 3,1-Hold,4285.19,3.059,0.437,5.786,0.7,73.66964006,1.311,,,,,,,,,,
Load 3,1-Hold,4301.19,3.059,0.437,5.686,0.7,72.39640051,1.311,,,,,,,,,,
Load 3,1-Hold,4317.19,3.059,0.437,5.686,0.7,72.39640051,1.311,,,,,,,,,,
Load 3,1-Hold,4333.19,3.059,0.437,5.986,0.7,76.21611915,1.311,,,,,,,,,,
Load 3,1-Hold,4349.19,3.059,0.437,5.586,0.7,71.12316097,1.311,,,,,,,,,,
Load 3,1-Hold,4365.19,3.059,0.437,5.986,0.7,76.21611915,1.311,,,,,,,,,,
Load 3,1-Hold,4381.19,3.059,0.437,5.686,0.7,72.39640051,1.311,,,,,,,,,,
Load 3,1-Hold,4397.19,3.059,0.437,6.086,0.7,77.48935869,1.311,,,,,,,,,,
Load 3,1-Hold,4413.19,3.059,0.437,5.886,0.7,74.9428796,1.311,,,,,,,,,,
Load 3,1-Hold,4429.19,3.059,0.437,5.786,0.7,73.66964006,1.311,,,,,,,,,,
Load 3,1-Hold,4445.19,3.059,0.437,5.886,0.7,74.9428796,1.311,,,,,,,,,,
Load 3,1-Hold,4461.19,3.059,0.437,5.986,0.7,76.21611915,1.311,,,,,,,,,,
Load 3,1-Hold,4477.19,3.059,0.437,5.986,0.7,76.21611915,1.311,,,,,,,,,,
Load 3,1-Hold,4493.19,3.059,0.437,5.986,0.7,76.21611915,1.311,,,,,,,,,,
Load 3,1-Hold,4509.19,3.059,0.437,5.986,0.7,76.21611915,1.311,,,,,,,,,,
Load 3,1-Hold,4525.19,3.059,0.437,5.986,0.7,76.21611915,1.311,,,,,,,,,,
Load 3,1-Hold,4541.19,3.059,0.437,5.986,0.7,76.21611915,1.311,,,,,,,,,,
Load 3,1-Hold,4557.19,3.059,0.437,5.986,0.7,76.21611915,1.311,,,,,,,,,,
Load 3,1-Hold,4573.19,3.059,0.437,5.986,0.7,76.21611915,1.311,,,,,,,,,,
Load 3,1-Hold,4589.19,3.059,0.437,5.986,0.7,76.21611915,1.311,,,,,,,,,,
Load 3,1-Hold,4605.19,3.059,0.437,5.986,0.7,76.21611915,1.311,,,,,,,,,,
Load 3,1-Hold,4621.19,3.059,0.437,5.986,0.7,76.21611915,1.311,,,,,,,,,,
Load 3,1-Hold,4637.19,3.059,0.437,5.986,0.7,76.21611915,1.311,,,,,,,,,,
Load 3,1-Hold,4653.19,3.059,0.437,5.986,0.7,76.21611915,1.311,,,,,,,,,,
Load 3,1-Hold,4669.19,3.059,0.437,5.986,0.7,76.21611915,1.311,,,,,,,,,,
Load 3,1-Hold,4685.19,3.059,0.437,5.586,0.7,71.12316097,1.311,,,,,,,,,,
Load 3,1-Hold,4701.19,3.059,0.437,5.986,0.7,76.21611915,1.311,,,,,,,,,,
Load 3,1-Hold,4717.19,3.059,0.437,5.486,0.7,69.84992142,1.311,,,,,,,,,,
Load 3,1-Hold,4733.19,3.059,0.437,5.786,0.7,73.66964006,1.311,,,,,,,,,,
Load 3,1-Hold,4749.19,3.059,0.437,5.286,0.7,67.30344233,1.311,,,,,,,,,,
Load 3,1-Hold,4765.19,3.059,0.437,5.886,0.7,74.9428796,1.311,,,,,,,,,,
Load 3,1-Hold,4781.19,3.059,0.437,5.186,0.7,66.03020279,1.311,,,,,,,,,,
Load 3,1-Hold,4797.19,3.059,0.437,5.186,0.7,66.03020279,1.311,,,,,,,,,,
Load 3,1-Hold,4813.19,3.059,0.437,5.186,0.7,66.03020279,1.311,,,,,,,,,,
Load 4,1-Compress,4829.19,3.043,0.016,7.686,0.696338673,97.86119141,1.327,,,,,,,,,,
Load 4,1-Compress,4845.19,3.027,0.032,9.586,0.692677346,122.0527428,1.343,,,,,,,,,,
Load 4,1-Compress,4861.19,3.011,0.048,12.386,0.689016018,157.70345,1.359,,,,,,,,,,
Load 4,1-Compress,4877.19,2.995,0.064,14.086,0.685354691,179.3485223,1.375,,,,,,,,,,
Load 4,1-Compress,4893.19,2.979,0.08,17.187,0.681693364,218.8316806,1.391,,,,,,,,,,
Load 4,1-Compress,4909.19,2.963,0.096,19.987,0.678032037,254.4823878,1.407,,,,,,,,,,
Load 4,1-Compress,4925.19,2.948,0.111,21.487,0.674599542,273.580981,1.422,,,,,,,,,,
Load 4,1-Compress,4941.19,2.931,0.128,24.387,0.670709382,310.5049278,1.439,,,,,,,,,,
Load 4,1-Compress,4957.19,2.915,0.144,26.788,0.667048055,341.0754092,1.455,,,,,,,,,,
Load 4,1-Compress,4973.19,2.899,0.16,27.688,0.663386728,352.5345651,1.471,,,,,,,,,,
Load 4,1-Compress,4989.19,2.884,0.175,29.288,0.659954233,372.9063979,1.486,,,,,,,,,,
Load 4,1-Compress,5005.19,2.868,0.191,29.988,0.656292906,381.8190747,1.502,,,,,,,,,,
Load 4,1-Compress,5021.19,2.851,0.208,31.488,0.652402746,400.9176678,1.519,,,,,,,,,,
Load 4,1-Compress,5037.19,2.835,0.224,32.388,0.648741419,412.3768237,1.535,,,,,,,,,,
Load 4,1-Compress,5053.19,2.819,0.24,31.688,0.645080092,403.4641469,1.551,,,,,,,,,,
Load 4,1-Compress,5069.19,2.803,0.256,31.688,0.641418764,403.4641469,1.567,,,,,,,,,,
Load 4,1-Compress,5085.19,2.787,0.272,32.388,0.637757437,412.3768237,1.583,,,,,,,,,,
Load 4,1-Compress,5101.19,2.771,0.288,32.288,0.63409611,411.1035842,1.599,,,,,,,,,,
Load 4,1-Compress,5117.19,2.756,0.303,31.588,0.630663616,402.1909074,1.614,,,,,,,,,,
Load 4,1-Compress,5133.19,2.74,0.319,31.588,0.627002288,402.1909074,1.63,,,,,,,,,,
Load 4,1-Compress,5149.19,2.723,0.336,32.388,0.623112128,412.3768237,1.647,,,,,,,,,,
Load 4,1-Compress,5165.19,2.707,0.352,32.888,0.619450801,418.7430215,1.663,,,,,,,,,,
Load 4,1-Compress,5181.19,2.691,0.368,32.388,0.615789474,412.3768237,1.679,,,,,,,,,,
Load 4,1-Compress,5197.19,2.676,0.383,32.488,0.612356979,413.6500633,1.694,,,,,,,,,,
Load 4,1-Compress,5213.19,2.659,0.4,33.288,0.608466819,423.8359797,1.711,,,,,,,,,,
Load 4,1-Compress,5229.19,2.643,0.416,33.988,0.604805492,432.7486565,1.727,,,,,,,,,,
Load 4,1-Compress,5245.19,2.627,0.432,33.988,0.601144165,432.7486565,1.743,,,,,,,,,,
Load 4,1-Hold,5260.48,2.622,0.437,30.588,0.6,389.4585119,1.748,,,,,,,,,,
Load 4,1-Hold,5276.48,2.622,0.437,26.188,0.6,333.435972,1.748,,,,,,,,,,
Load 4,1-Hold,5292.48,2.622,0.437,23.287,0.6,296.4992928,1.748,,,,,,,,,,
Load 4,1-Hold,5308.48,2.622,0.437,20.587,0.6,262.1218251,1.748,,,,,,,,,,
Load 4,1-Hold,5324.48,2.622,0.437,18.987,0.6,241.7499924,1.748,,,,,,,,,,
Load 4,1-Hold,5340.48,2.622,0.437,17.487,0.6,222.6513992,1.748,,,,,,,,,,
Load 4,1-Hold,5356.48,2.622,0.437,16.987,0.6,216.2852015,1.748,,,,,,,,,,
Load 4,1-Hold,5372.48,2.622,0.437,15.587,0.6,198.4598478,1.748,,,,,,,,,,
Load 4,1-Hold,5388.48,2.622,0.437,15.086,0.6,192.0809177,1.748,,,,,,,,,,
Load 4,1-Hold,5404.48,2.622,0.437,14.286,0.6,181.8950014,1.748,,,,,,,,,,
Load 4,1-Hold,5420.48,2.622,0.437,13.586,0.6,172.9823245,1.748,,,,,,,,,,
Load 4,1-Hold,5436.48,2.622,0.437,13.186,0.6,167.8893664,1.748,,,,,,,,,,
Load 4,1-Hold,5452.48,2.622,0.437,13.186,0.6,167.8893664,1.748,,,,,,,,,,
Load 4,1-Hold,5468.48,2.622,0.437,12.786,0.6,162.7964082,1.748,,,,,,,,,,
Load 4,1-Hold,5484.48,2.622,0.437,12.386,0.6,157.70345,1.748,,,,,,,,,,
Load 4,1-Hold,5500.48,2.622,0.437,12.186,0.6,155.1569709,1.748,,,,,,,,,,
Load 4,1-Hold,5516.48,2.622,0.437,11.586,0.6,147.5175337,1.748,,,,,,,,,,
Load 4,1-Hold,5532.48,2.622,0.437,11.486,0.6,146.2442941,1.748,,,,,,,,,,
Load 4,1-Hold,5548.48,2.622,0.437,11.586,0.6,147.5175337,1.748,,,,,,,,,,
Load 4,1-Hold,5564.48,2.622,0.437,11.086,0.6,141.1513359,1.748,,,,,,,,,,
Load 4,1-Hold,5580.48,2.622,0.437,10.986,0.6,139.8780964,1.748,,,,,,,,,,
Load 4,1-Hold,5596.48,2.622,0.437,10.786,0.6,137.3316173,1.748,,,,,,,,,,
Load 4,1-Hold,5612.48,2.622,0.437,10.786,0.6,137.3316173,1.748,,,,,,,,,,
Load 4,1-Hold,5628.48,2.622,0.437,10.286,0.6,130.9654196,1.748,,,,,,,,,,
Load 4,1-Hold,5644.48,2.622,0.437,10.186,0.6,129.69218,1.748,,,,,,,,,,
Load 4,1-Hold,5660.48,2.622,0.437,10.086,0.6,128.4189405,1.748,,,,,,,,,,
Load 4,1-Hold,5676.48,2.622,0.437,9.986,0.6,127.1457009,1.748,,,,,,,,,,
Load 4,1-Hold,5692.48,2.622,0.437,9.986,0.6,127.1457009,1.748,,,,,,,,,,
Load 4,1-Hold,5708.48,2.622,0.437,9.586,0.6,122.0527428,1.748,,,,,,,,,,
Load 4,1-Hold,5724.48,2.622,0.437,9.586,0.6,122.0527428,1.748,,,,,,,,,,
Load 4,1-Hold,5740.48,2.622,0.437,9.486,0.6,120.7795032,1.748,,,,,,,,,,
Load 4,1-Hold,5756.48,2.622,0.437,9.486,0.6,120.7795032,1.748,,,,,,,,,,
Load 4,1-Hold,5772.48,2.622,0.437,9.386,0.6,119.5062637,1.748,,,,,,,,,,
Load 4,1-Hold,5788.48,2.622,0.437,9.586,0.6,122.0527428,1.748,,,,,,,,,,
Load 4,1-Hold,5804.48,2.622,0.437,9.586,0.6,122.0527428,1.748,,,,,,,,,,
Load 4,1-Hold,5820.48,2.622,0.437,9.686,0.6,123.3259823,1.748,,,,,,,,,,
Load 4,1-Hold,5836.48,2.622,0.437,9.386,0.6,119.5062637,1.748,,,,,,,,,,
Load 4,1-Hold,5852.48,2.622,0.437,9.286,0.6,118.2330241,1.748,,,,,,,,,,
Load 4,1-Hold,5868.48,2.622,0.437,9.186,0.6,116.9597846,1.748,,,,,,,,,,
Load 4,1-Hold,5884.48,2.622,0.437,9.186,0.6,116.9597846,1.748,,,,,,,,,,
Load 4,1-Hold,5900.48,2.622,0.437,9.186,0.6,116.9597846,1.748,,,,,,,,,,
Load 4,1-Hold,5916.48,2.622,0.437,9.186,0.6,116.9597846,1.748,,,,,,,,,,
Load 4,1-Hold,5932.48,2.622,0.437,9.086,0.6,115.686545,1.748,,,,,,,,,,
Load 4,1-Hold,5948.48,2.622,0.437,8.986,0.6,114.4133055,1.748,,,,,,,,,,
Load 4,1-Hold,5964.48,2.622,0.437,8.986,0.6,114.4133055,1.748,,,,,,,,,,
Load 4,1-Hold,5980.48,2.622,0.437,8.886,0.6,113.1400659,1.748,,,,,,,,,,
Load 4,1-Hold,5996.48,2.622,0.437,8.986,0.6,114.4133055,1.748,,,,,,,,,,
Load 4,1-Hold,6012.48,2.622,0.437,8.886,0.6,113.1400659,1.748,,,,,,,,,,
Load 4,1-Hold,6028.48,2.622,0.437,8.486,0.6,108.0471078,1.748,,,,,,,,,,
Load 4,1-Hold,6044.48,2.622,0.437,8.486,0.6,108.0471078,1.748,,,,,,,,,,
Load 4,1-Hold,6060.48,2.622,0.437,8.486,0.6,108.0471078,1.748,,,,,,,,,,
Load 4,1-Hold,6076.48,2.622,0.437,8.386,0.6,106.7738682,1.748,,,,,,,,,,
Load 4,1-Hold,6092.48,2.622,0.437,8.486,0.6,108.0471078,1.748,,,,,,,,,,
Load 4,1-Hold,6108.48,2.622,0.437,8.386,0.6,106.7738682,1.748,,,,,,,,,,
Load 4,1-Hold,6124.48,2.622,0.437,8.386,0.6,106.7738682,1.748,,,,,,,,,,
Load 4,1-Hold,6140.48,2.622,0.437,8.386,0.6,106.7738682,1.748,,,,,,,,,,
Load 4,1-Hold,6156.48,2.622,0.437,8.386,0.6,106.7738682,1.748,,,,,,,,,,
Load 4,1-Hold,6172.48,2.622,0.437,8.386,0.6,106.7738682,1.748,,,,,,,,,,
Load 4,1-Hold,6188.48,2.622,0.437,8.386,0.6,106.7738682,1.748,,,,,,,,,,
Load 4,1-Hold,6204.48,2.622,0.437,8.286,0.6,105.5006287,1.748,,,,,,,,,,
Load 4,1-Hold,6220.48,2.622,0.437,8.186,0.6,104.2273891,1.748,,,,,,,,,,
Load 4,1-Hold,6236.48,2.622,0.437,8.186,0.6,104.2273891,1.748,,,,,,,,,,
Load 4,1-Hold,6252.48,2.622,0.437,8.186,0.6,104.2273891,1.748,,,,,,,,,,
Load 4,1-Hold,6268.48,2.622,0.437,8.186,0.6,104.2273891,1.748,,,,,,,,,,
Load 4,1-Hold,6284.48,2.622,0.437,8.186,0.6,104.2273891,1.748,,,,,,,,,,
Load 4,1-Hold,6300.48,2.622,0.437,8.086,0.6,102.9541496,1.748,,,,,,,,,,
Load 4,1-Hold,6316.48,2.622,0.437,7.986,0.6,101.68091,1.748,,,,,,,,,,
Load 4,1-Hold,6332.48,2.622,0.437,7.986,0.6,101.68091,1.748,,,,,,,,,,
Load 4,1-Hold,6348.48,2.622,0.437,7.986,0.6,101.68091,1.748,,,,,,,,,,
Load 4,1-Hold,6364.48,2.622,0.437,7.886,0.6,100.4076705,1.748,,,,,,,,,,
Load 4,1-Hold,6380.48,2.622,0.437,7.986,0.6,101.68091,1.748,,,,,,,,,,
Load 4,1-Hold,6396.48,2.622,0.437,7.886,0.6,100.4076705,1.748,,,,,,,,,,
Load 4,1-Hold,6412.48,2.622,0.437,7.886,0.6,100.4076705,1.748,,,,,,,,,,
Load 4,1-Hold,6428.48,2.622,0.437,7.786,0.6,99.13443095,1.748,,,,,,,,,,
Load 4,1-Hold,6444.48,2.622,0.437,7.786,0.6,99.13443095,1.748,,,,,,,,,,
Load 4,1-Hold,6460.48,2.622,0.437,7.786,0.6,99.13443095,1.748,,,,,,,,,,
Load 4,1-Hold,6476.48,2.622,0.437,7.786,0.6,99.13443095,1.748,,,,,,,,,,
Load 4,1-Hold,6492.48,2.622,0.437,7.686,0.6,97.86119141,1.748,,,,,,,,,,
Load 4,1-Hold,6508.48,2.622,0.437,7.686,0.6,97.86119141,1.748,,,,,,,,,,
Load 4,1-Hold,6524.48,2.622,0.437,7.686,0.6,97.86119141,1.748,,,,,,,,,,
Load 4,1-Hold,6540.48,2.622,0.437,7.886,0.6,100.4076705,1.748,,,,,,,,,,
Load 4,1-Hold,6556.48,2.622,0.437,7.786,0.6,99.13443095,1.748,,,,,,,,,,
Load 4,1-Hold,6572.48,2.622,0.437,7.686,0.6,97.86119141,1.748,,,,,,,,,,
Load 4,1-Hold,6588.48,2.622,0.437,7.686,0.6,97.86119141,1.748,,,,,,,,,,
Load 4,1-Hold,6604.48,2.622,0.437,7.686,0.6,97.86119141,1.748,,,,,,,,,,
Load 4,1-Hold,6620.48,2.622,0.437,7.686,0.6,97.86119141,1.748,,,,,,,,,,
Load 4,1-Hold,6636.48,2.622,0.437,7.686,0.6,97.86119141,1.748,,,,,,,,,,
Load 4,1-Hold,6652.48,2.622,0.437,7.686,0.6,97.86119141,1.748,,,,,,,,,,
Load 4,1-Hold,6668.48,2.622,0.437,7.686,0.6,97.86119141,1.748,,,,,,,,,,
Load 4,1-Hold,6684.48,2.622,0.437,7.786,0.6,99.13443095,1.748,,,,,,,,,,
Load 4,1-Hold,6700.48,2.622,0.437,7.786,0.6,99.13443095,1.748,,,,,,,,,,
Load 4,1-Hold,6716.48,2.622,0.437,7.786,0.6,99.13443095,1.748,,,,,,,,,,
Load 4,1-Hold,6732.48,2.622,0.437,7.786,0.6,99.13443095,1.748,,,,,,,,,,
Load 4,1-Hold,6748.48,2.622,0.437,7.786,0.6,99.13443095,1.748,,,,,,,,,,
Load 5,1-Compress,6764.47,2.609,0.013,9.586,0.597025172,122.0527428,1.761,,,,,,,,,,
Load 5,1-Compress,6780.47,2.593,0.029,11.686,0.593363844,148.7907732,1.777,,,,,,,,,,
Load 5,1-Compress,6796.47,2.577,0.045,14.686,0.589702517,186.9879595,1.793,,,,,,,,,,
Load 5,1-Compress,6812.47,2.561,0.061,16.787,0.58604119,213.7387224,1.809,,,,,,,,,,
Load 5,1-Compress,6828.47,2.545,0.077,20.087,0.582379863,255.7556274,1.825,,,,,,,,,,
Load 5,1-Compress,6844.47,2.529,0.093,22.687,0.578718535,288.8598555,1.841,,,,,,,,,,
Load 5,1-Compress,6860.47,2.513,0.109,25.988,0.575057208,330.8894929,1.857,,,,,,,,,,
Load 5,1-Compress,6876.47,2.497,0.125,29.388,0.571395881,374.1796374,1.873,,,,,,,,,,
Load 5,1-Compress,6892.47,2.481,0.141,31.188,0.567734554,397.0979492,1.889,,,,,,,,,,
Load 5,1-Compress,6908.47,2.465,0.157,33.188,0.564073227,422.5627401,1.905,,,,,,,,,,
Load 5,1-Compress,6924.47,2.449,0.173,35.188,0.560411899,448.027531,1.921,,,,,,,,,,
Load 5,1-Compress,6940.47,2.433,0.189,36.889,0.556750572,469.6853357,1.937,,,,,,,,,,
Load 5,1-Compress,6956.47,2.418,0.204,37.389,0.553318078,476.0515334,1.952,,,,,,,,,,
Load 5,1-Compress,6972.47,2.4,0.222,38.089,0.549199085,484.9642102,1.97,,,,,,,,,,
Load 5,1-Compress,6988.47,2.385,0.237,38.789,0.54576659,493.876887,1.985,,,,,,,,,,
Load 5,1-Compress,7004.47,2.369,0.253,39.389,0.542105263,501.5163243,2.001,,,,,,,,,,
Load 5,1-Compress,7020.47,2.353,0.269,39.389,0.538443936,501.5163243,2.017,,,,,,,,,,
Load 5,1-Compress,7036.47,2.337,0.285,38.989,0.534782609,496.4233661,2.033,,,,,,,,,,
Load 5,1-Compress,7052.47,2.322,0.3,39.589,0.531350114,504.0628034,2.048,,,,,,,,,,
Load 5,1-Compress,7068.47,2.305,0.317,39.989,0.527459954,509.1557615,2.065,,,,,,,,,,
Load 5,1-Compress,7084.47,2.289,0.333,40.189,0.523798627,511.7022406,2.081,,,,,,,,,,
Load 5,1-Compress,7100.47,2.273,0.349,40.389,0.5201373,514.2487197,2.097,,,,,,,,,,
Load 5,1-Compress,7116.47,2.257,0.365,40.589,0.516475973,516.7951988,2.113,,,,,,,,,,
Load 5,1-Compress,7132.47,2.241,0.381,41.789,0.512814645,532.0740733,2.129,,,,,,,,,,
Load 5,1-Compress,7148.47,2.226,0.396,41.289,0.509382151,525.7078756,2.144,,,,,,,,,,
Load 5,1-Compress,7164.47,2.209,0.413,41.789,0.505491991,532.0740733,2.161,,,,,,,,,,
Load 5,1-Compress,7180.47,2.193,0.429,42.389,0.501830664,539.7135106,2.177,,,,,,,,,,
Load 5,1-Hold,7195.76,2.185,0.437,39.289,0.5,500.2430847,2.185,,,,,,,,,,
Load 5,1-Hold,7211.76,2.185,0.437,34.388,0.5,437.8416146,2.185,,,,,,,,,,
Load 5,1-Hold,7227.76,2.185,0.437,30.788,0.5,392.004991,2.185,,,,,,,,,,
Load 5,1-Hold,7243.76,2.185,0.437,27.788,0.5,353.8078047,2.185,,,,,,,,,,
Load 5,1-Hold,7259.76,2.185,0.437,25.988,0.5,330.8894929,2.185,,,,,,,,,,
Load 5,1-Hold,7275.76,2.185,0.437,24.287,0.5,309.2316882,2.185,,,,,,,,,,
Load 5,1-Hold,7291.76,2.185,0.437,22.687,0.5,288.8598555,2.185,,,,,,,,,,
Load 5,1-Hold,7307.76,2.185,0.437,21.587,0.5,274.8542205,2.185,,,,,,,,,,
Load 5,1-Hold,7323.76,2.185,0.437,20.487,0.5,260.8485855,2.185,,,,,,,,,,
Load 5,1-Hold,7339.76,2.185,0.437,19.687,0.5,250.6626692,2.185,,,,,,,,,,
Load 5,1-Hold,7355.76,2.185,0.437,18.787,0.5,239.2035133,2.185,,,,,,,,,,
Load 5,1-Hold,7371.76,2.185,0.437,18.387,0.5,234.1105551,2.185,,,,,,,,,,
Load 5,1-Hold,7387.76,2.185,0.437,17.787,0.5,226.4711178,2.185,,,,,,,,,,
Load 5,1-Hold,7403.76,2.185,0.437,17.187,0.5,218.8316806,2.185,,,,,,,,,,
Load 5,1-Hold,7419.76,2.185,0.437,16.887,0.5,215.0119619,2.185,,,,,,,,,,
Load 5,1-Hold,7435.76,2.185,0.437,16.687,0.5,212.4654828,2.185,,,,,,,,,,
Load 5,1-Hold,7451.76,2.185,0.437,16.087,0.5,204.8260456,2.185,,,,,,,,,,
Load 5,1-Hold,7467.76,2.185,0.437,15.787,0.5,201.0063269,2.185,,,,,,,,,,
Load 5,1-Hold,7483.76,2.185,0.437,15.487,0.5,197.1866083,2.185,,,,,,,,,,
Load 5,1-Hold,7499.76,2.185,0.437,15.187,0.5,193.3668897,2.185,,,,,,,,,,
Load 5,1-Hold,7515.76,2.185,0.437,15.187,0.5,193.3668897,2.185,,,,,,,,,,
Load 5,1-Hold,7531.76,2.185,0.437,14.786,0.5,188.2611991,2.185,,,,,,,,,,
Load 5,1-Hold,7547.76,2.185,0.437,14.586,0.5,185.71472,2.185,,,,,,,,,,
Load 5,1-Hold,7563.76,2.185,0.437,14.486,0.5,184.4414804,2.185,,,,,,,,,,
Load 5,1-Hold,7579.76,2.185,0.437,14.286,0.5,181.8950014,2.185,,,,,,,,,,
Load 5,1-Hold,7595.76,2.185,0.437,13.986,0.5,178.0752827,2.185,,,,,,,,,,
Load 5,1-Hold,7611.76,2.185,0.437,13.686,0.5,174.2555641,2.185,,,,,,,,,,
Load 5,1-Hold,7627.76,2.185,0.437,13.686,0.5,174.2555641,2.185,,,,,,,,,,
Load 5,1-Hold,7643.76,2.185,0.437,13.386,0.5,170.4358455,2.185,,,,,,,,,,
Load 5,1-Hold,7659.76,2.185,0.437,13.286,0.5,169.1626059,2.185,,,,,,,,,,
Load 5,1-Hold,7675.76,2.185,0.437,13.186,0.5,167.8893664,2.185,,,,,,,,,,
Load 5,1-Hold,7691.76,2.185,0.437,13.186,0.5,167.8893664,2.185,,,,,,,,,,
Load 5,1-Hold,7707.76,2.185,0.437,13.186,0.5,167.8893664,2.185,,,,,,,,,,
Load 5,1-Hold,7723.76,2.185,0.437,13.186,0.5,167.8893664,2.185,,,,,,,,,,
Load 5,1-Hold,7739.76,2.185,0.437,12.786,0.5,162.7964082,2.185,,,,,,,,,,
Load 5,1-Hold,7755.76,2.185,0.437,12.786,0.5,162.7964082,2.185,,,,,,,,,,
Load 5,1-Hold,7771.76,2.185,0.437,12.786,0.5,162.7964082,2.185,,,,,,,,,,
Load 5,1-Hold,7787.76,2.185,0.437,12.786,0.5,162.7964082,2.185,,,,,,,,,,
Load 5,1-Hold,7803.76,2.185,0.437,12.486,0.5,158.9766896,2.185,,,,,,,,,,
Load 5,1-Hold,7819.76,2.185,0.437,12.386,0.5,157.70345,2.185,,,,,,,,,,
Load 5,1-Hold,7835.76,2.185,0.437,12.386,0.5,157.70345,2.185,,,,,,,,,,
Load 5,1-Hold,7851.76,2.185,0.437,12.286,0.5,156.4302105,2.185,,,,,,,,,,
Load 5,1-Hold,7867.76,2.185,0.437,12.086,0.5,153.8837314,2.185,,,,,,,,,,
Load 5,1-Hold,7883.76,2.185,0.437,11.986,0.5,152.6104918,2.185,,,,,,,,,,
Load 5,1-Hold,7899.76,2.185,0.437,11.986,0.5,152.6104918,2.185,,,,,,,,,,
Load 5,1-Hold,7915.76,2.185,0.437,11.986,0.5,152.6104918,2.185,,,,,,,,,,
Load 5,1-Hold,7931.76,2.185,0.437,11.986,0.5,152.6104918,2.185,,,,,,,,,,
Load 5,1-Hold,7947.76,2.185,0.437,11.986,0.5,152.6104918,2.185,,,,,,,,,,
Load 5,1-Hold,7963.76,2.185,0.437,11.986,0.5,152.6104918,2.185,,,,,,,,,,
Load 5,1-Hold,7979.76,2.185,0.437,11.786,0.5,150.0640127,2.185,,,,,,,,,,
Load 5,1-Hold,7995.76,2.185,0.437,11.686,0.5,148.7907732,2.185,,,,,,,,,,
Load 5,1-Hold,8011.76,2.185,0.437,11.586,0.5,147.5175337,2.185,,,,,,,,,,
Load 5,1-Hold,8027.76,2.185,0.437,11.586,0.5,147.5175337,2.185,,,,,,,,,,
Load 5,1-Hold,8043.76,2.185,0.437,11.586,0.5,147.5175337,2.185,,,,,,,,,,
Load 5,1-Hold,8059.76,2.185,0.437,11.586,0.5,147.5175337,2.185,,,,,,,,,,
Load 5,1-Hold,8075.76,2.185,0.437,11.286,0.5,143.697815,2.185,,,,,,,,,,
Load 5,1-Hold,8091.76,2.185,0.437,11.486,0.5,146.2442941,2.185,,,,,,,,,,
Load 5,1-Hold,8107.76,2.185,0.437,11.486,0.5,146.2442941,2.185,,,,,,,,,,
Load 5,1-Hold,8123.76,2.185,0.437,11.486,0.5,146.2442941,2.185,,,,,,,,,,
Load 5,1-Hold,8139.76,2.185,0.437,11.486,0.5,146.2442941,2.185,,,,,,,,,,
Load 5,1-Hold,8155.76,2.185,0.437,11.386,0.5,144.9710546,2.185,,,,,,,,,,
Load 5,1-Hold,8171.76,2.185,0.437,11.586,0.5,147.5175337,2.185,,,,,,,,,,
Load 5,1-Hold,8187.76,2.185,0.437,11.286,0.5,143.697815,2.185,,,,,,,,,,
Load 5,1-Hold,8203.76,2.185,0.437,11.486,0.5,146.2442941,2.185,,,,,,,,,,
Load 5,1-Hold,8219.76,2.185,0.437,11.586,0.5,147.5175337,2.185,,,,,,,,,,
Load 5,1-Hold,8235.76,2.185,0.437,11.386,0.5,144.9710546,2.185,,,,,,,,,,
Load 5,1-Hold,8251.76,2.185,0.437,11.286,0.5,143.697815,2.185,,,,,,,,,,
Load 5,1-Hold,8267.76,2.185,0.437,11.286,0.5,143.697815,2.185,,,,,,,,,,
Load 5,1-Hold,8283.76,2.185,0.437,11.286,0.5,143.697815,2.185,,,,,,,,,,
Load 5,1-Hold,8299.76,2.185,0.437,11.186,0.5,142.4245755,2.185,,,,,,,,,,
Load 5,1-Hold,8315.76,2.185,0.437,11.186,0.5,142.4245755,2.185,,,,,,,,,,
Load 5,1-Hold,8331.76,2.185,0.437,11.286,0.5,143.697815,2.185,,,,,,,,,,
Load 5,1-Hold,8347.76,2.185,0.437,11.286,0.5,143.697815,2.185,,,,,,,,,,
Load 5,1-Hold,8363.76,2.185,0.437,11.186,0.5,142.4245755,2.185,,,,,,,,,,
Load 5,1-Hold,8379.76,2.185,0.437,11.186,0.5,142.4245755,2.185,,,,,,,,,,
Load 5,1-Hold,8395.76,2.185,0.437,11.186,0.5,142.4245755,2.185,,,,,,,,,,
Load 5,1-Hold,8411.76,2.185,0.437,11.186,0.5,142.4245755,2.185,,,,,,,,,,
Load 5,1-Hold,8427.76,2.185,0.437,11.286,0.5,143.697815,2.185,,,,,,,,,,
Load 5,1-Hold,8443.76,2.185,0.437,11.186,0.5,142.4245755,2.185,,,,,,,,,,
Load 5,1-Hold,8459.76,2.185,0.437,11.186,0.5,142.4245755,2.185,,,,,,,,,,
Load 5,1-Hold,8475.76,2.185,0.437,11.086,0.5,141.1513359,2.185,,,,,,,,,,
Load 5,1-Hold,8491.76,2.185,0.437,11.186,0.5,142.4245755,2.185,,,,,,,,,,
Load 5,1-Hold,8507.76,2.185,0.437,10.786,0.5,137.3316173,2.185,,,,,,,,,,
Load 5,1-Hold,8523.76,2.185,0.437,10.886,0.5,138.6048568,2.185,,,,,,,,,,
Load 5,1-Hold,8539.76,2.185,0.437,10.786,0.5,137.3316173,2.185,,,,,,,,,,
Load 5,1-Hold,8555.76,2.185,0.437,10.786,0.5,137.3316173,2.185,,,,,,,,,,
Load 5,1-Hold,8571.76,2.185,0.437,10.786,0.5,137.3316173,2.185,,,,,,,,,,
Load 5,1-Hold,8587.76,2.185,0.437,10.786,0.5,137.3316173,2.185,,,,,,,,,,
Load 5,1-Hold,8603.76,2.185,0.437,10.786,0.5,137.3316173,2.185,,,,,,,,,,
Load 5,1-Hold,8619.76,2.185,0.437,10.786,0.5,137.3316173,2.185,,,,,,,,,,
Load 5,1-Hold,8635.76,2.185,0.437,10.786,0.5,137.3316173,2.185,,,,,,,,,,
Load 5,1-Hold,8651.76,2.185,0.437,10.786,0.5,137.3316173,2.185,,,,,,,,,,
Load 5,1-Hold,8667.76,2.185,0.437,10.786,0.5,137.3316173,2.185,,,,,,,,,,
Load 5,1-Hold,8683.76,2.185,0.437,10.686,0.5,136.0583777,2.185,,,,,,,,,,
Load 6,1-Compress,8699.76,2.175,0.01,13.286,0.49771167,169.1626059,2.195,,,,,,,,,,
Load 6,1-Compress,8715.76,2.16,0.025,15.987,0.494279176,203.552806,2.21,,,,,,,,,,
Load 6,1-Compress,8731.76,2.143,0.042,18.587,0.490389016,236.6570342,2.227,,,,,,,,,,
Load 6,1-Compress,8747.76,2.127,0.058,21.987,0.486727689,279.9471787,2.243,,,,,,,,,,
Load 6,1-Compress,8763.76,2.111,0.074,25.588,0.483066362,325.7965347,2.259,,,,,,,,,,
Load 6,1-Compress,8779.76,2.096,0.089,28.388,0.479633867,361.447242,2.274,,,,,,,,,,
Load 6,1-Compress,8795.76,2.08,0.105,31.488,0.47597254,400.9176678,2.29,,,,,,,,,,
Load 6,1-Compress,8811.76,2.063,0.122,34.388,0.47208238,437.8416146,2.307,,,,,,,,,,
Load 6,1-Compress,8827.76,2.047,0.138,37.589,0.468421053,478.5980125,2.323,,,,,,,,,,
Load 6,1-Compress,8843.76,2.031,0.154,40.889,0.464759725,520.6149174,2.339,,,,,,,,,,
Load 6,1-Compress,8859.76,2.015,0.17,42.189,0.461098398,537.1670315,2.355,,,,,,,,,,
Load 6,1-Compress,8875.76,1.999,0.186,43.989,0.457437071,560.0853433,2.371,,,,,,,,,,
Load 6,1-Compress,8891.76,1.983,0.202,45.289,0.453775744,576.6374574,2.387,,,,,,,,,,
Load 6,1-Compress,8907.76,1.967,0.218,47.29,0.450114416,602.1149807,2.403,,,,,,,,,,
Load 6,1-Compress,8923.76,1.951,0.234,47.89,0.446453089,609.754418,2.419,,,,,,,,,,
Load 6,1-Compress,8939.76,1.935,0.25,47.59,0.442791762,605.9346993,2.435,,,,,,,,,,
Load 6,1-Compress,8955.76,1.919,0.266,48.09,0.439130435,612.3008971,2.451,,,,,,,,,,
Load 6,1-Compress,8971.76,1.903,0.282,48.79,0.435469108,621.2135739,2.467,,,,,,,,,,
Load 6,1-Compress,8987.76,1.888,0.297,48.19,0.432036613,613.5741366,2.482,,,,,,,,,,
Load 6,1-Compress,9003.76,1.871,0.314,48.49,0.428146453,617.3938552,2.499,,,,,,,,,,
Load 6,1-Compress,9019.76,1.855,0.33,48.79,0.424485126,621.2135739,2.515,,,,,,,,,,
Load 6,1-Compress,9035.76,1.839,0.346,49.59,0.420823799,631.3994902,2.531,,,,,,,,,,
Load 6,1-Compress,9051.76,1.824,0.361,49.69,0.417391304,632.6727298,2.546,,,,,,,,,,
Load 6,1-Compress,9067.76,1.808,0.377,49.39,0.413729977,628.8530111,2.562,,,,,,,,,,
Load 6,1-Compress,9083.76,1.792,0.393,49.69,0.41006865,632.6727298,2.578,,,,,,,,,,
Load 6,1-Compress,9099.76,1.775,0.41,51.09,0.40617849,650.4980834,2.595,,,,,,,,,,
Load 6,1-Compress,9115.76,1.76,0.425,50.79,0.402745995,646.6783648,2.61,,,,,,,,,,
Load 6,1-Hold,9131.05,1.748,0.437,48.99,0.4,623.760053,2.622,,,,,,,,,,
Load 6,1-Hold,9147.05,1.748,0.437,42.889,0.4,546.0797083,2.622,,,,,,,,,,
Load 6,1-Hold,9163.05,1.748,0.437,38.889,0.4,495.1501266,2.622,,,,,,,,,,
Load 6,1-Hold,9179.05,1.748,0.437,35.188,0.4,448.027531,2.622,,,,,,,,,,
Load 6,1-Hold,9195.05,1.748,0.437,32.588,0.4,414.9233028,2.622,,,,,,,,,,
Load 6,1-Hold,9211.05,1.748,0.437,30.788,0.4,392.004991,2.622,,,,,,,,,,
Load 6,1-Hold,9227.05,1.748,0.437,28.588,0.4,363.993721,2.622,,,,,,,,,,
Load 6,1-Hold,9243.05,1.748,0.437,27.488,0.4,349.9880861,2.622,,,,,,,,,,
Load 6,1-Hold,9259.05,1.748,0.437,26.088,0.4,332.1627324,2.622,,,,,,,,,,
Load 6,1-Hold,9275.05,1.748,0.437,24.687,0.4,314.3246464,2.622,,,,,,,,,,
Load 6,1-Hold,9291.05,1.748,0.437,24.187,0.4,307.9584487,2.622,,,,,,,,,,
Load 6,1-Hold,9307.05,1.748,0.437,23.287,0.4,296.4992928,2.622,,,,,,,,,,
Load 6,1-Hold,9323.05,1.748,0.437,22.287,0.4,283.7668973,2.622,,,,,,,,,,
Load 6,1-Hold,9339.05,1.748,0.437,21.487,0.4,273.580981,2.622,,,,,,,,,,
Load 6,1-Hold,9355.05,1.748,0.437,21.187,0.4,269.7612623,2.622,,,,,,,,,,
Load 6,1-Hold,9371.05,1.748,0.437,20.587,0.4,262.1218251,2.622,,,,,,,,,,
Load 6,1-Hold,9387.05,1.748,0.437,20.187,0.4,257.0288669,2.622,,,,,,,,,,
Load 6,1-Hold,9403.05,1.748,0.437,19.587,0.4,249.3894296,2.622,,,,,,,,,,
Load 6,1-Hold,9419.05,1.748,0.437,19.087,0.4,243.0232319,2.622,,,,,,,,,,
Load 6,1-Hold,9435.05,1.748,0.437,18.787,0.4,239.2035133,2.622,,,,,,,,,,
Load 6,1-Hold,9451.05,1.748,0.437,18.187,0.4,231.564076,2.622,,,,,,,,,,
Load 6,1-Hold,9467.05,1.748,0.437,18.087,0.4,230.2908365,2.622,,,,,,,,,,
Load 6,1-Hold,9483.05,1.748,0.437,17.687,0.4,225.1978783,2.622,,,,,,,,,,
Load 6,1-Hold,9499.05,1.748,0.437,17.387,0.4,221.3781596,2.622,,,,,,,,,,
Load 6,1-Hold,9515.05,1.748,0.437,17.187,0.4,218.8316806,2.622,,,,,,,,,,
Load 6,1-Hold,9531.05,1.748,0.437,16.787,0.4,213.7387224,2.622,,,,,,,,,,
Load 6,1-Hold,9547.05,1.748,0.437,16.987,0.4,216.2852015,2.622,,,,,,,,,,
Load 6,1-Hold,9563.05,1.748,0.437,16.787,0.4,213.7387224,2.622,,,,,,,,,,
Load 6,1-Hold,9579.05,1.748,0.437,16.387,0.4,208.6457642,2.622,,,,,,,,,,
Load 6,1-Hold,9595.05,1.748,0.437,16.387,0.4,208.6457642,2.622,,,,,,,,,,
Load 6,1-Hold,9611.05,1.748,0.437,16.287,0.4,207.3725247,2.622,,,,,,,,,,
Load 6,1-Hold,9627.05,1.748,0.437,15.687,0.4,199.7330874,2.622,,,,,,,,,,
Load 6,1-Hold,9643.05,1.748,0.437,15.587,0.4,198.4598478,2.622,,,,,,,,,,
Load 6,1-Hold,9659.05,1.748,0.437,15.487,0.4,197.1866083,2.622,,,,,,,,,,
Load 6,1-Hold,9675.05,1.748,0.437,15.387,0.4,195.9133687,2.622,,,,,,,,,,
Load 6,1-Hold,9691.05,1.748,0.437,14.986,0.4,190.8076782,2.622,,,,,,,,,,
Load 6,1-Hold,9707.05,1.748,0.437,14.886,0.4,189.5344386,2.622,,,,,,,,,,
Load 6,1-Hold,9723.05,1.748,0.437,14.786,0.4,188.2611991,2.622,,,,,,,,,,
Load 6,1-Hold,9739.05,1.748,0.437,14.986,0.4,190.8076782,2.622,,,,,,,,,,
Load 6,1-Hold,9755.05,1.748,0.437,14.886,0.4,189.5344386,2.622,,,,,,,,,,
Load 6,1-Hold,9771.05,1.748,0.437,14.786,0.4,188.2611991,2.622,,,,,,,,,,
Load 6,1-Hold,9787.05,1.748,0.437,14.786,0.4,188.2611991,2.622,,,,,,,,,,
Load 6,1-Hold,9803.05,1.748,0.437,14.286,0.4,181.8950014,2.622,,,,,,,,,,
Load 6,1-Hold,9819.05,1.748,0.437,14.286,0.4,181.8950014,2.622,,,,,,,,,,
Load 6,1-Hold,9835.05,1.748,0.437,14.186,0.4,180.6217618,2.622,,,,,,,,,,
Load 6,1-Hold,9851.05,1.748,0.437,14.286,0.4,181.8950014,2.622,,,,,,,,,,
Load 6,1-Hold,9867.05,1.748,0.437,14.086,0.4,179.3485223,2.622,,,,,,,,,,
Load 6,1-Hold,9883.05,1.748,0.437,14.086,0.4,179.3485223,2.622,,,,,,,,,,
Load 6,1-Hold,9899.05,1.748,0.437,13.986,0.4,178.0752827,2.622,,,,,,,,,,
Load 6,1-Hold,9915.05,1.748,0.437,13.886,0.4,176.8020432,2.622,,,,,,,,,,
Load 6,1-Hold,9931.05,1.748,0.437,13.586,0.4,172.9823245,2.622,,,,,,,,,,
Load 6,1-Hold,9947.05,1.748,0.437,13.386,0.4,170.4358455,2.622,,,,,,,,,,
Load 6,1-Hold,9963.05,1.748,0.437,13.286,0.4,169.1626059,2.622,,,,,,,,,,
Load 6,1-Hold,9979.05,1.748,0.437,13.286,0.4,169.1626059,2.622,,,,,,,,,,
Load 6,1-Hold,9995.05,1.748,0.437,13.386,0.4,170.4358455,2.622,,,,,,,,,,
Load 6,1-Hold,10011.05,1.748,0.437,13.186,0.4,167.8893664,2.622,,,,,,,,,,
Load 6,1-Hold,10027.05,1.748,0.437,13.286,0.4,169.1626059,2.622,,,,,,,,,,
Load 6,1-Hold,10043.05,1.748,0.437,13.286,0.4,169.1626059,2.622,,,,,,,,,,
Load 6,1-Hold,10059.05,1.748,0.437,13.086,0.4,166.6161268,2.622,,,,,,,,,,
Load 6,1-Hold,10075.05,1.748,0.437,13.286,0.4,169.1626059,2.622,,,,,,,,,,
Load 6,1-Hold,10091.05,1.748,0.437,12.986,0.4,165.3428873,2.622,,,,,,,,,,
Load 6,1-Hold,10107.05,1.748,0.437,12.986,0.4,165.3428873,2.622,,,,,,,,,,
Load 6,1-Hold,10123.05,1.748,0.437,13.186,0.4,167.8893664,2.622,,,,,,,,,,
Load 6,1-Hold,10139.05,1.748,0.437,13.186,0.4,167.8893664,2.622,,,,,,,,,,
Load 6,1-Hold,10155.05,1.748,0.437,13.186,0.4,167.8893664,2.622,,,,,,,,,,
Load 6,1-Hold,10171.05,1.748,0.437,13.086,0.4,166.6161268,2.622,,,,,,,,,,
Load 6,1-Hold,10187.05,1.748,0.437,12.986,0.4,165.3428873,2.622,,,,,,,,,,
Load 6,1-Hold,10203.05,1.748,0.437,12.986,0.4,165.3428873,2.622,,,,,,,,,,
Load 6,1-Hold,10219.05,1.748,0.437,13.086,0.4,166.6161268,2.622,,,,,,,,,,
Load 6,1-Hold,10235.05,1.748,0.437,12.986,0.4,165.3428873,2.622,,,,,,,,,,
Load 6,1-Hold,10251.05,1.748,0.437,12.886,0.4,164.0696477,2.622,,,,,,,,,,
Load 6,1-Hold,10267.05,1.748,0.437,12.886,0.4,164.0696477,2.622,,,,,,,,,,
Load 6,1-Hold,10283.05,1.748,0.437,12.686,0.4,161.5231686,2.622,,,,,,,,,,
Load 6,1-Hold,10299.05,1.748,0.437,12.386,0.4,157.70345,2.622,,,,,,,,,,
Load 6,1-Hold,10315.05,1.748,0.437,12.486,0.4,158.9766896,2.622,,,,,,,,,,
Load 6,1-Hold,10331.05,1.748,0.437,12.386,0.4,157.70345,2.622,,,,,,,,,,
Load 6,1-Hold,10347.05,1.748,0.437,12.586,0.4,160.2499291,2.622,,,,,,,,,,
Load 6,1-Hold,10363.05,1.748,0.437,12.586,0.4,160.2499291,2.622,,,,,,,,,,
Load 6,1-Hold,10379.05,1.748,0.437,12.386,0.4,157.70345,2.622,,,,,,,,,,
Load 6,1-Hold,10395.05,1.748,0.437,12.386,0.4,157.70345,2.622,,,,,,,,,,
Load 6,1-Hold,10411.05,1.748,0.437,12.386,0.4,157.70345,2.622,,,,,,,,,,
Load 6,1-Hold,10427.05,1.748,0.437,12.386,0.4,157.70345,2.622,,,,,,,,,,
Load 6,1-Hold,10443.05,1.748,0.437,12.386,0.4,157.70345,2.622,,,,,,,,,,
Load 6,1-Hold,10459.05,1.748,0.437,12.386,0.4,157.70345,2.622,,,,,,,,,,
Load 6,1-Hold,10475.05,1.748,0.437,12.286,0.4,156.4302105,2.622,,,,,,,,,,
Load 6,1-Hold,10491.05,1.748,0.437,12.286,0.4,156.4302105,2.622,,,,,,,,,,
Load 6,1-Hold,10507.05,1.748,0.437,12.186,0.4,155.1569709,2.622,,,,,,,,,,
Load 6,1-Hold,10523.05,1.748,0.437,12.186,0.4,155.1569709,2.622,,,,,,,,,,
Load 6,1-Hold,10539.05,1.748,0.437,12.186,0.4,155.1569709,2.622,,,,,,,,,,
Load 6,1-Hold,10555.05,1.748,0.437,12.186,0.4,155.1569709,2.622,,,,,,,,,,
Load 6,1-Hold,10571.05,1.748,0.437,12.186,0.4,155.1569709,2.622,,,,,,,,,,
Load 6,1-Hold,10587.05,1.748,0.437,11.986,0.4,152.6104918,2.622,,,,,,,,,,
Load 6,1-Hold,10603.05,1.748,0.437,12.186,0.4,155.1569709,2.622,,,,,,,,,,
Load 6,1-Hold,10619.05,1.748,0.437,12.086,0.4,153.8837314,2.622,,,,,,,,,,
Load 6,1-Hold,10628.05,1.748,0.437,11.886,0.4,151.3372523,2.622,,,,,,,,,,