File: training_data/P01_Test005Data.csv
SetName,Cycle,Time_S,Size_mm,Displacement_mm,Force_N,Stretch,Stress [kPa],Disp,,,,,,,,,,Area
Load 1,1-Compress,0,3.781,0,0.127,1,1.617014222,0,,,,,,,,,,78.53981634
Load 1,1-Compress,19,3.761,0.02,0.327,0.994710394,4.163493311,0.02,,,,,,,,,,
Load 1,1-Compress,38,3.742,0.039,0.428,0.989685268,5.449465251,0.039,,,,,,,,,,
Load 1,1-Compress,57,3.723,0.058,0.327,0.984660143,4.163493311,0.058,,,,,,,,,,
Load 1,1-Compress,76,3.704,0.077,0.629,0.979635017,8.008676736,0.077,,,,,,,,,,
Load 1,1-Compress,95,3.686,0.095,0.729,0.974874372,9.281916281,0.095,,,,,,,,,,
Load 1,1-Compress,114,3.667,0.114,1.03,0.969849246,13.11436731,0.114,,,,,,,,,,
Load 1,1-Compress,133,3.647,0.134,1.03,0.96455964,13.11436731,0.134,,,,,,,,,,
Load 1,1-Compress,152,3.628,0.153,1.231,0.959534515,15.6735788,0.153,,,,,,,,,,
Load 1,1-Compress,171,3.609,0.172,1.03,0.954509389,13.11436731,0.172,,,,,,,,,,
Load 1,1-Compress,190,3.59,0.191,1.331,0.949484263,16.94681834,0.191,,,,,,,,,,
Load 1,1-Compress,209,3.571,0.21,1.834,0.944459138,23.35121325,0.21,,,,,,,,,,
Load 1,1-Compress,228,3.552,0.229,1.532,0.939434012,19.50602983,0.229,,,,,,,,,,
Load 1,1-Compress,247,3.533,0.248,1.532,0.934408887,19.50602983,0.248,,,,,,,,,,
Load 1,1-Compress,266,3.515,0.266,1.432,0.929648241,18.23279028,0.266,,,,,,,,,,
Load 1,1-Compress,285,3.496,0.285,1.934,0.924623116,24.6244528,0.285,,,,,,,,,,
Load 1,1-Compress,304,3.477,0.304,2.034,0.91959799,25.89769234,0.304,,,,,,,,,,
Load 1,1-Compress,323,3.457,0.324,2.034,0.914308384,25.89769234,0.324,,,,,,,,,,
Load 1,1-Compress,342,3.438,0.343,2.637,0.909283258,33.57532679,0.343,,,,,,,,,,
Load 1,1-Compress,361,3.42,0.361,2.737,0.904522613,34.84856634,0.361,,,,,,,,,,
Load 1,1-Hold,379.25,3.403,0.378,2.737,0.900026448,34.84856634,0.378,,,,,,,,,,
Load 1,1-Hold,398.25,3.403,0.378,1.532,0.900026448,19.50602983,0.378,,,,,,,,,,
Load 1,1-Hold,417.25,3.403,0.378,1.633,0.900026448,20.79200177,0.378,,,,,,,,,,
Load 1,1-Hold,436.25,3.403,0.378,1.532,0.900026448,19.50602983,0.378,,,,,,,,,,
Load 1,1-Hold,455.25,3.403,0.378,1.03,0.900026448,13.11436731,0.378,,,,,,,,,,
Load 1,1-Hold,474.25,3.403,0.378,1.03,0.900026448,13.11436731,0.378,,,,,,,,,,
Load 1,1-Hold,493.25,3.403,0.378,1.03,0.900026448,13.11436731,0.378,,,,,,,,,,
Load 1,1-Hold,512.25,3.403,0.378,0.829,0.900026448,10.55515583,0.378,,,,,,,,,,
Load 1,1-Hold,531.25,3.403,0.378,1.03,0.900026448,13.11436731,0.378,,,,,,,,,,
Load 1,1-Hold,550.25,3.403,0.378,0.629,0.900026448,8.008676736,0.378,,,,,,,,,,
Load 1,1-Hold,569.25,3.403,0.378,0.428,0.900026448,5.449465251,0.378,,,,,,,,,,
Load 1,1-Hold,588.25,3.403,0.378,0.829,0.900026448,10.55515583,0.378,,,,,,,,,,
Load 1,1-Hold,607.25,3.403,0.378,0.528,0.900026448,6.722704796,0.378,,,,,,,,,,
Load 1,1-Hold,626.25,3.403,0.378,0.428,0.900026448,5.449465251,0.378,,,,,,,,,,
Load 1,1-Hold,645.25,3.403,0.378,0.327,0.900026448,4.163493311,0.378,,,,,,,,,,
Load 1,1-Hold,664.25,3.403,0.378,0.227,0.900026448,2.890253767,0.378,,,,,,,,,,
Load 1,1-Hold,683.25,3.403,0.378,0.227,0.900026448,2.890253767,0.378,,,,,,,,,,
Load 1,1-Hold,702.25,3.403,0.378,0.327,0.900026448,4.163493311,0.378,,,,,,,,,,
Load 1,1-Hold,721.25,3.403,0.378,0.227,0.900026448,2.890253767,0.378,,,,,,,,,,
Load 1,1-Hold,740.25,3.403,0.378,0.227,0.900026448,2.890253767,0.378,,,,,,,,,,
Load 1,1-Hold,759.25,3.403,0.378,0.227,0.900026448,2.890253767,0.378,,,,,,,,,,
Load 1,1-Hold,778.25,3.403,0.378,0.227,0.900026448,2.890253767,0.378,,,,,,,,,,
Load 1,1-Hold,797.25,3.403,0.378,0.227,0.900026448,2.890253767,0.378,,,,,,,,,,
Load 1,1-Hold,816.25,3.403,0.378,0.227,0.900026448,2.890253767,0.378,,,,,,,,,,
Load 1,1-Hold,835.25,3.403,0.378,0.227,0.900026448,2.890253767,0.378,,,,,,,,,,
Load 1,1-Hold,854.25,3.403,0.378,0.227,0.900026448,2.890253767,0.378,,,,,,,,,,
Load 1,1-Hold,873.25,3.403,0.378,0.227,0.900026448,2.890253767,0.378,,,,,,,,,,
Load 1,1-Hold,892.25,3.403,0.378,0.227,0.900026448,2.890253767,0.378,,,,,,,,,,
Load 1,1-Hold,911.25,3.403,0.378,0.227,0.900026448,2.890253767,0.378,,,,,,,,,,
Load 1,1-Hold,930.25,3.403,0.378,0.227,0.900026448,2.890253767,0.378,,,,,,,,,,
Load 1,1-Hold,949.25,3.403,0.378,0.227,0.900026448,2.890253767,0.378,,,,,,,,,,
Load 1,1-Hold,968.25,3.403,0.378,0.227,0.900026448,2.890253767,0.378,,,,,,,,,,
Load 1,1-Hold,987.25,3.403,0.378,0.227,0.900026448,2.890253767,0.378,,,,,,,,,,
Load 1,1-Hold,1006.25,3.403,0.378,0.227,0.900026448,2.890253767,0.378,,,,,,,,,,
Load 1,1-Hold,1025.25,3.403,0.378,0.227,0.900026448,2.890253767,0.378,,,,,,,,,,
Load 1,1-Hold,1044.25,3.403,0.378,0.127,0.900026448,1.617014222,0.378,,,,,,,,,,
Load 1,1-Hold,1063.25,3.403,0.378,-0.175,0.900026448,-2.228169203,0.378,,,,,,,,,,
Load 1,1-Hold,1082.25,3.403,0.378,0.127,0.900026448,1.617014222,0.378,,,,,,,,,,
Load 1,1-Hold,1101.25,3.403,0.378,0.127,0.900026448,1.617014222,0.378,,,,,,,,,,
Load 1,1-Hold,1120.25,3.403,0.378,-0.074,0.900026448,-0.942197263,0.378,,,,,,,,,,
Load 1,1-Hold,1139.25,3.403,0.378,0.227,0.900026448,2.890253767,0.378,,,,,,,,,,
Load 1,1-Hold,1158.25,3.403,0.378,-0.175,0.900026448,-2.228169203,0.378,,,,,,,,,,
Load 1,1-Hold,1177.25,3.403,0.378,-0.074,0.900026448,-0.942197263,0.378,,,,,,,,,,
Load 1,1-Hold,1196.25,3.403,0.378,-0.275,0.900026448,-3.501408748,0.378,,,,,,,,,,
Load 1,1-Hold,1215.25,3.403,0.378,-0.175,0.900026448,-2.228169203,0.378,,,,,,,,,,
Load 1,1-Hold,1234.25,3.403,0.378,0.026,0.900026448,0.331042282,0.378,,,,,,,,,,
Load 1,1-Hold,1253.25,3.403,0.378,0.127,0.900026448,1.617014222,0.378,,,,,,,,,,
Load 1,1-Hold,1272.25,3.403,0.378,-0.275,0.900026448,-3.501408748,0.378,,,,,,,,,,
Load 1,1-Hold,1291.25,3.403,0.378,-0.476,0.900026448,-6.060620233,0.378,,,,,,,,,,
Load 1,1-Hold,1310.25,3.403,0.378,-0.275,0.900026448,-3.501408748,0.378,,,,,,,,,,
Load 1,1-Hold,1329.25,3.403,0.378,-0.074,0.900026448,-0.942197263,0.378,,,,,,,,,,
Load 1,1-Hold,1348.25,3.403,0.378,-0.275,0.900026448,-3.501408748,0.378,,,,,,,,,,
Load 1,1-Hold,1367.25,3.403,0.378,-0.275,0.900026448,-3.501408748,0.378,,,,,,,,,,
Load 1,1-Hold,1386.25,3.403,0.378,-0.376,0.900026448,-4.787380688,0.378,,,,,,,,,,
Load 1,1-Hold,1405.25,3.403,0.378,-0.074,0.900026448,-0.942197263,0.378,,,,,,,,,,
Load 1,1-Hold,1424.25,3.403,0.378,-0.376,0.900026448,-4.787380688,0.378,,,,,,,,,,
Load 1,1-Hold,1443.25,3.403,0.378,-0.476,0.900026448,-6.060620233,0.378,,,,,,,,,,
Load 1,1-Hold,1462.25,3.403,0.378,-0.275,0.900026448,-3.501408748,0.378,,,,,,,,,,
Load 1,1-Hold,1481.25,3.403,0.378,-0.275,0.900026448,-3.501408748,0.378,,,,,,,,,,
Load 1,1-Hold,1500.25,3.403,0.378,-0.476,0.900026448,-6.060620233,0.378,,,,,,,,,,
Load 1,1-Hold,1519.25,3.403,0.378,-0.074,0.900026448,-0.942197263,0.378,,,,,,,,,,
Load 1,1-Hold,1538.25,3.403,0.378,-0.376,0.900026448,-4.787380688,0.378,,,,,,,,,,
Load 1,1-Hold,1557.25,3.403,0.378,-0.376,0.900026448,-4.787380688,0.378,,,,,,,,,,
Load 1,1-Hold,1576.25,3.403,0.378,-0.175,0.900026448,-2.228169203,0.378,,,,,,,,,,
Load 1,1-Hold,1595.25,3.403,0.378,-0.476,0.900026448,-6.060620233,0.378,,,,,,,,,,
Load 1,1-Hold,1614.25,3.403,0.378,-0.376,0.900026448,-4.787380688,0.378,,,,,,,,,,
Load 1,1-Hold,1633.25,3.403,0.378,-0.476,0.900026448,-6.060620233,0.378,,,,,,,,,,
Load 1,1-Hold,1652.25,3.403,0.378,-0.476,0.900026448,-6.060620233,0.378,,,,,,,,,,
Load 1,1-Hold,1671.25,3.403,0.378,-0.576,0.900026448,-7.333859778,0.378,,,,,,,,,,
Load 1,1-Hold,1690.25,3.403,0.378,-0.576,0.900026448,-7.333859778,0.378,,,,,,,,,,
Load 1,1-Hold,1709.25,3.403,0.378,-0.576,0.900026448,-7.333859778,0.378,,,,,,,,,,
Load 1,1-Hold,1728.25,3.403,0.378,-0.576,0.900026448,-7.333859778,0.378,,,,,,,,,,
Load 1,1-Hold,1747.25,3.403,0.378,-0.576,0.900026448,-7.333859778,0.378,,,,,,,,,,
Load 1,1-Hold,1766.25,3.403,0.378,-0.576,0.900026448,-7.333859778,0.378,,,,,,,,,,
Load 1,1-Hold,1785.25,3.403,0.378,-0.576,0.900026448,-7.333859778,0.378,,,,,,,,,,
Load 1,1-Hold,1804.25,3.403,0.378,-0.576,0.900026448,-7.333859778,0.378,,,,,,,,,,
Load 1,1-Hold,1823.25,3.403,0.378,-0.576,0.900026448,-7.333859778,0.378,,,,,,,,,,
Load 1,1-Hold,1842.25,3.403,0.378,-0.576,0.900026448,-7.333859778,0.378,,,,,,,,,,
Load 1,1-Hold,1861.25,3.403,0.378,-0.677,0.900026448,-8.619831718,0.378,,,,,,,,,,
Load 2,1-Compress,1880.25,3.401,0.002,0.829,0.899497487,10.55515583,0.38,,,,,,,,,,
Load 2,1-Compress,1899.25,3.382,0.021,1.03,0.894472362,13.11436731,0.399,,,,,,,,,,
Load 2,1-Compress,1918.25,3.363,0.04,1.131,0.889447236,14.40033925,0.418,,,,,,,,,,
Load 2,1-Compress,1937.25,3.345,0.058,1.532,0.884686591,19.50602983,0.436,,,,,,,,,,
Load 2,1-Compress,1956.25,3.325,0.078,2.737,0.879396985,34.84856634,0.456,,,,,,,,,,
Load 2,1-Compress,1975.25,3.306,0.097,3.44,0.874371859,43.79944034,0.475,,,,,,,,,,
Load 2,1-Compress,1994.25,3.287,0.116,4.745,0.869346734,60.4152164,0.494,,,,,,,,,,
Load 2,1-Compress,2013.25,3.268,0.135,5.248,0.864321608,66.81961131,0.513,,,,,,,,,,
Load 2,1-Compress,2032.25,3.25,0.153,5.649,0.859560963,71.92530188,0.531,,,,,,,,,,
Load 2,1-Compress,2051.25,3.23,0.173,6.653,0.854271357,84.70862691,0.551,,,,,,,,,,
Load 2,1-Compress,2070.25,3.211,0.192,6.955,0.849246231,88.55381034,0.57,,,,,,,,,,
Load 2,1-Compress,2089.25,3.192,0.211,7.256,0.844221106,92.38626137,0.589,,,,,,,,,,
Load 2,1-Compress,2108.25,3.173,0.23,8.159,0.83919598,103.8836145,0.608,,,,,,,,,,
Load 2,1-Compress,2127.25,3.154,0.249,8.662,0.834170854,110.2880094,0.627,,,,,,,,,,
Load 2,1-Compress,2146.25,3.135,0.268,9.063,0.829145729,115.3936999,0.646,,,,,,,,,,
Load 2,1-Compress,2165.25,3.117,0.286,9.164,0.824385083,116.6796719,0.664,,,,,,,,,,
Load 2,1-Compress,2184.25,3.098,0.305,9.866,0.819359958,125.6178135,0.683,,,,,,,,,,
Load 2,1-Compress,2203.25,3.078,0.325,10.67,0.814070352,135.8546594,0.703,,,,,,,,,,
Load 2,1-Compress,2222.25,3.059,0.344,10.67,0.809045226,135.8546594,0.722,,,,,,,,,,
Load 2,1-Compress,2241.25,3.04,0.363,10.77,0.804020101,137.127899,0.741,,,,,,,,,,
Load 2,1-Hold,2259.49,3.025,0.378,10.168,0.800052896,129.4629969,0.756,,,,,,,,,,
Load 2,1-Hold,2278.49,3.025,0.378,7.457,0.800052896,94.94547285,0.756,,,,,,,,,,
Load 2,1-Hold,2297.49,3.025,0.378,5.85,0.800052896,74.48451337,0.756,,,,,,,,,,
Load 2,1-Hold,2316.49,3.025,0.378,5.248,0.800052896,66.81961131,0.756,,,,,,,,,,
Load 2,1-Hold,2335.49,3.025,0.378,4.344,0.800052896,55.30952582,0.756,,,,,,,,,,
Load 2,1-Hold,2354.49,3.025,0.378,3.942,0.800052896,50.19110285,0.756,,,,,,,,,,
Load 2,1-Hold,2373.49,3.025,0.378,3.44,0.800052896,43.79944034,0.756,,,,,,,,,,
Load 2,1-Hold,2392.49,3.025,0.378,3.44,0.800052896,43.79944034,0.756,,,,,,,,,,
Load 2,1-Hold,2411.49,3.025,0.378,3.038,0.800052896,38.68101737,0.756,,,,,,,,,,
Load 2,1-Hold,2430.49,3.025,0.378,2.737,0.800052896,34.84856634,0.756,,,,,,,,,,
Load 2,1-Hold,2449.49,3.025,0.378,2.637,0.800052896,33.57532679,0.756,,,,,,,,,,
Load 2,1-Hold,2468.49,3.025,0.378,2.637,0.800052896,33.57532679,0.756,,,,,,,,,,
Load 2,1-Hold,2487.49,3.025,0.378,2.536,0.800052896,32.28935485,0.756,,,,,,,,,,
Load 2,1-Hold,2506.49,3.025,0.378,2.235,0.800052896,28.45690382,0.756,,,,,,,,,,
Load 2,1-Hold,2525.49,3.025,0.378,1.934,0.800052896,24.6244528,0.756,,,,,,,,,,
Load 2,1-Hold,2544.49,3.025,0.378,2.336,0.800052896,29.74287577,0.756,,,,,,,,,,
Load 2,1-Hold,2563.49,3.025,0.378,2.034,0.800052896,25.89769234,0.756,,,,,,,,,,
Load 2,1-Hold,2582.49,3.025,0.378,1.934,0.800052896,24.6244528,0.756,,,,,,,,,,
Load 2,1-Hold,2601.49,3.025,0.378,1.834,0.800052896,23.35121325,0.756,,,,,,,,,,
Load 2,1-Hold,2620.49,3.025,0.378,1.834,0.800052896,23.35121325,0.756,,,,,,,,,,
Load 2,1-Hold,2639.49,3.025,0.378,1.834,0.800052896,23.35121325,0.756,,,,,,,,,,
Load 2,1-Hold,2658.49,3.025,0.378,1.834,0.800052896,23.35121325,0.756,,,,,,,,,,
Load 2,1-Hold,2677.49,3.025,0.378,1.231,0.800052896,15.6735788,0.756,,,,,,,,,,
Load 2,1-Hold,2696.49,3.025,0.378,1.532,0.800052896,19.50602983,0.756,,,,,,,,,,
Load 2,1-Hold,2715.49,3.025,0.378,1.331,0.800052896,16.94681834,0.756,,,,,,,,,,
Load 2,1-Hold,2734.49,3.025,0.378,1.733,0.800052896,22.06524131,0.756,,,,,,,,,,
Load 2,1-Hold,2753.49,3.025,0.378,1.834,0.800052896,23.35121325,0.756,,,,,,,,,,
Load 2,1-Hold,2772.49,3.025,0.378,1.834,0.800052896,23.35121325,0.756,,,,,,,,,,
Load 2,1-Hold,2791.49,3.025,0.378,1.733,0.800052896,22.06524131,0.756,,,,,,,,,,
Load 2,1-Hold,2810.49,3.025,0.378,1.633,0.800052896,20.79200177,0.756,,,,,,,,,,
Load 2,1-Hold,2829.49,3.025,0.378,1.834,0.800052896,23.35121325,0.756,,,,,,,,,,
Load 2,1-Hold,2848.49,3.025,0.378,1.633,0.800052896,20.79200177,0.756,,,,,,,,,,
Load 2,1-Hold,2867.49,3.025,0.378,1.733,0.800052896,22.06524131,0.756,,,,,,,,,,
Load 2,1-Hold,2886.49,3.025,0.378,1.733,0.800052896,22.06524131,0.756,,,,,,,,,,
Load 2,1-Hold,2905.49,3.025,0.378,1.432,0.800052896,18.23279028,0.756,,,,,,,,,,
Load 2,1-Hold,2924.49,3.025,0.378,1.633,0.800052896,20.79200177,0.756,,,,,,,,,,
Load 2,1-Hold,2943.49,3.025,0.378,1.633,0.800052896,20.79200177,0.756,,,,,,,,,,
Load 2,1-Hold,2962.49,3.025,0.378,1.532,0.800052896,19.50602983,0.756,,,,,,,,,,
Load 2,1-Hold,2981.49,3.025,0.378,1.733,0.800052896,22.06524131,0.756,,,,,,,,,,
Load 2,1-Hold,3000.49,3.025,0.378,1.432,0.800052896,18.23279028,0.756,,,,,,,,,,
Load 2,1-Hold,3019.49,3.025,0.378,1.532,0.800052896,19.50602983,0.756,,,,,,,,,,
Load 2,1-Hold,3038.49,3.025,0.378,1.532,0.800052896,19.50602983,0.756,,,,,,,,,,
Load 2,1-Hold,3057.49,3.025,0.378,1.131,0.800052896,14.40033925,0.756,,,,,,,,,,
Load 2,1-Hold,3076.49,3.025,0.378,1.03,0.800052896,13.11436731,0.756,,,,,,,,,,
Load 2,1-Hold,3095.49,3.025,0.378,1.03,0.800052896,13.11436731,0.756,,,,,,,,,,
Load 2,1-Hold,3114.49,3.025,0.378,1.03,0.800052896,13.11436731,0.756,,,,,,,,,,
Load 2,1-Hold,3133.49,3.025,0.378,1.03,0.800052896,13.11436731,0.756,,,,,,,,,,
Load 2,1-Hold,3152.49,3.025,0.378,1.03,0.800052896,13.11436731,0.756,,,,,,,,,,
Load 2,1-Hold,3171.49,3.025,0.378,0.93,0.800052896,11.84112777,0.756,,,,,,,,,,
Load 2,1-Hold,3190.49,3.025,0.378,1.03,0.800052896,13.11436731,0.756,,,,,,,,,,
Load 2,1-Hold,3209.49,3.025,0.378,0.829,0.800052896,10.55515583,0.756,,,,,,,,,,
Load 2,1-Hold,3228.49,3.025,0.378,1.03,0.800052896,13.11436731,0.756,,,,,,,,,,
Load 2,1-Hold,3247.49,3.025,0.378,1.03,0.800052896,13.11436731,0.756,,,,,,,,,,
Load 2,1-Hold,3266.49,3.025,0.378,0.829,0.800052896,10.55515583,0.756,,,,,,,,,,
Load 2,1-Hold,3285.49,3.025,0.378,1.03,0.800052896,13.11436731,0.756,,,,,,,,,,
Load 2,1-Hold,3304.49,3.025,0.378,0.829,0.800052896,10.55515583,0.756,,,,,,,,,,
Load 2,1-Hold,3323.49,3.025,0.378,0.93,0.800052896,11.84112777,0.756,,,,,,,,,,
Load 2,1-Hold,3342.49,3.025,0.378,1.03,0.800052896,13.11436731,0.756,,,,,,,,,,
Load 2,1-Hold,3361.49,3.025,0.378,0.829,0.800052896,10.55515583,0.756,,,,,,,,,,
Load 2,1-Hold,3380.49,3.025,0.378,0.93,0.800052896,11.84112777,0.756,,,,,,,,,,
Load 2,1-Hold,3399.49,3.025,0.378,1.03,0.800052896,13.11436731,0.756,,,,,,,,,,
Load 2,1-Hold,3418.49,3.025,0.378,1.03,0.800052896,13.11436731,0.756,,,,,,,,,,
Load 2,1-Hold,3437.49,3.025,0.378,1.03,0.800052896,13.11436731,0.756,,,,,,,,,,
Load 2,1-Hold,3456.49,3.025,0.378,0.729,0.800052896,9.281916281,0.756,,,,,,,,,,
Load 2,1-Hold,3475.49,3.025,0.378,0.829,0.800052896,10.55515583,0.756,,,,,,,,,,
Load 2,1-Hold,3494.49,3.025,0.378,1.03,0.800052896,13.11436731,0.756,,,,,,,,,,
Load 2,1-Hold,3513.49,3.025,0.378,0.629,0.800052896,8.008676736,0.756,,,,,,,,,,
Load 2,1-Hold,3532.49,3.025,0.378,0.829,0.800052896,10.55515583,0.756,,,,,,,,,,
Load 2,1-Hold,3551.49,3.025,0.378,0.93,0.800052896,11.84112777,0.756,,,,,,,,,,
Load 2,1-Hold,3570.49,3.025,0.378,0.729,0.800052896,9.281916281,0.756,,,,,,,,,,
Load 2,1-Hold,3589.49,3.025,0.378,0.729,0.800052896,9.281916281,0.756,,,,,,,,,,
Load 2,1-Hold,3608.49,3.025,0.378,0.327,0.800052896,4.163493311,0.756,,,,,,,,,,
Load 2,1-Hold,3627.49,3.025,0.378,0.528,0.800052896,6.722704796,0.756,,,,,,,,,,
Load 2,1-Hold,3646.49,3.025,0.378,0.93,0.800052896,11.84112777,0.756,,,,,,,,,,
Load 2,1-Hold,3665.49,3.025,0.378,0.629,0.800052896,8.008676736,0.756,,,,,,,,,,
Load 2,1-Hold,3684.49,3.025,0.378,0.227,0.800052896,2.890253767,0.756,,,,,,,,,,
Load 2,1-Hold,3703.49,3.025,0.378,0.829,0.800052896,10.55515583,0.756,,,,,,,,,,
Load 2,1-Hold,3722.49,3.025,0.378,0.729,0.800052896,9.281916281,0.756,,,,,,,,,,
Load 2,1-Hold,3741.49,3.025,0.378,1.03,0.800052896,13.11436731,0.756,,,,,,,,,,
Load 3,1-Compress,3760.48,3.022,0.003,1.532,0.799259455,19.50602983,0.759,,,,,,,,,,
Load 3,1-Compress,3779.48,3.003,0.022,2.336,0.79423433,29.74287577,0.778,,,,,,,,,,
Load 3,1-Compress,3798.48,2.984,0.041,4.243,0.789209204,54.02355388,0.797,,,,,,,,,,
Load 3,1-Compress,3817.48,2.965,0.06,6.452,0.784184078,82.14941543,0.816,,,,,,,,,,
Load 3,1-Compress,3836.48,2.946,0.079,8.963,0.779158953,114.1204604,0.835,,,,,,,,,,
Load 3,1-Compress,3855.48,2.928,0.097,10.268,0.774398307,130.7362365,0.853,,,,,,,,,,
Load 3,1-Compress,3874.48,2.908,0.117,11.975,0.769108701,152.4704355,0.873,,,,,,,,,,
Load 3,1-Compress,3893.48,2.889,0.136,13.18,0.764083576,167.812972,0.892,,,,,,,,,,
Load 3,1-Compress,3912.48,2.87,0.155,13.582,0.75905845,172.931395,0.911,,,,,,,,,,
Load 3,1-Compress,3931.48,2.852,0.173,14.184,0.754297805,180.596297,0.929,,,,,,,,,,
Load 3,1-Compress,3950.48,2.832,0.193,14.686,0.749008199,186.9879595,0.949,,,,,,,,,,
Load 3,1-Compress,3969.48,2.813,0.212,15.489,0.743983073,197.2120731,0.968,,,,,,,,,,
Load 3,1-Compress,3988.48,2.794,0.231,16.192,0.738957948,206.1629471,0.987,,,,,,,,,,
Load 3,1-Compress,4007.48,2.775,0.25,16.494,0.733932822,210.0081305,1.006,,,,,,,,,,
Load 3,1-Compress,4026.48,2.756,0.269,16.694,0.728907696,212.5546096,1.025,,,,,,,,,,
Load 3,1-Compress,4045.48,2.737,0.288,16.795,0.723882571,213.8405815,1.044,,,,,,,,,,
Load 3,1-Compress,4064.48,2.718,0.307,18,0.718857445,229.1831181,1.063,,,,,,,,,,
Load 3,1-Compress,4083.48,2.7,0.325,17.699,0.7140968,225.350667,1.081,,,,,,,,,,
Load 3,1-Compress,4102.48,2.681,0.344,17.899,0.709071674,227.8971461,1.1,,,,,,,,,,
Load 3,1-Compress,4121.48,2.661,0.364,18.703,0.703782068,238.1339921,1.12,,,,,,,,,,
Load 3,1-Hold,4139.73,2.647,0.378,18.1,0.700079344,230.4563576,1.134,,,,,,,,,,
Load 3,1-Hold,4158.73,2.647,0.378,13.983,0.700079344,178.0370855,1.134,,,,,,,,,,
Load 3,1-Hold,4177.73,2.647,0.378,11.774,0.700079344,149.911224,1.134,,,,,,,,,,
Load 3,1-Hold,4196.73,2.647,0.378,9.967,0.700079344,126.9037854,1.134,,,,,,,,,,
Load 3,1-Hold,4215.73,2.647,0.378,8.561,0.700079344,109.0020374,1.134,,,,,,,,,,
Load 3,1-Hold,4234.73,2.647,0.378,8.159,0.700079344,103.8836145,1.134,,,,,,,,,,
Load 3,1-Hold,4253.73,2.647,0.378,7.457,0.700079344,94.94547285,1.134,,,,,,,,,,
Load 3,1-Hold,4272.73,2.647,0.378,6.754,0.700079344,85.99459885,1.134,,,,,,,,,,
Load 3,1-Hold,4291.73,2.647,0.378,6.653,0.700079344,84.70862691,1.134,,,,,,,,,,
Load 3,1-Hold,4310.73,2.647,0.378,6.051,0.700079344,77.04372485,1.134,,,,,,,,,,
Load 3,1-Hold,4329.73,2.647,0.378,5.85,0.700079344,74.48451337,1.134,,,,,,,,,,
Load 3,1-Hold,4348.73,2.647,0.378,5.448,0.700079344,69.3660904,1.134,,,,,,,,,,
Load 3,1-Hold,4367.73,2.647,0.378,5.147,0.700079344,65.53363937,1.134,,,,,,,,,,
Load 3,1-Hold,4386.73,2.647,0.378,5.248,0.700079344,66.81961131,1.134,,,,,,,,,,
Load 3,1-Hold,4405.73,2.647,0.378,5.448,0.700079344,69.3660904,1.134,,,,,,,,,,
Load 3,1-Hold,4424.73,2.647,0.378,5.047,0.700079344,64.26039982,1.134,,,,,,,,,,
Load 3,1-Hold,4443.73,2.647,0.378,5.047,0.700079344,64.26039982,1.134,,,,,,,,,,
Load 3,1-Hold,4462.73,2.647,0.378,4.946,0.700079344,62.97442788,1.134,,,,,,,,,,
Load 3,1-Hold,4481.73,2.647,0.378,4.846,0.700079344,61.70118834,1.134,,,,,,,,,,
Load 3,1-Hold,4500.73,2.647,0.378,4.545,0.700079344,57.86873731,1.134,,,,,,,,,,
Load 3,1-Hold,4519.73,2.647,0.378,4.243,0.700079344,54.02355388,1.134,,,,,,,,,,
Load 3,1-Hold,4538.73,2.647,0.378,4.344,0.700079344,55.30952582,1.134,,,,,,,,,,
Load 3,1-Hold,4557.73,2.647,0.378,4.243,0.700079344,54.02355388,1.134,,,,,,,,,,
Load 3,1-Hold,4576.73,2.647,0.378,4.243,0.700079344,54.02355388,1.134,,,,,,,,,,
Load 3,1-Hold,4595.73,2.647,0.378,3.842,0.700079344,48.91786331,1.134,,,,,,,,,,
Load 3,1-Hold,4614.73,2.647,0.378,4.143,0.700079344,52.75031434,1.134,,,,,,,,,,
Load 3,1-Hold,4633.73,2.647,0.378,4.143,0.700079344,52.75031434,1.134,,,,,,,,,,
Load 3,1-Hold,4652.73,2.647,0.378,3.942,0.700079344,50.19110285,1.134,,,,,,,,,,
Load 3,1-Hold,4671.73,2.647,0.378,3.641,0.700079344,46.35865182,1.134,,,,,,,,,,
Load 3,1-Hold,4690.73,2.647,0.378,3.641,0.700079344,46.35865182,1.134,,,,,,,,,,
Load 3,1-Hold,4709.73,2.647,0.378,3.44,0.700079344,43.79944034,1.134,,,,,,,,,,
Load 3,1-Hold,4728.73,2.647,0.378,3.44,0.700079344,43.79944034,1.134,,,,,,,,,,
Load 3,1-Hold,4747.73,2.647,0.378,3.641,0.700079344,46.35865182,1.134,,,,,,,,,,
Load 3,1-Hold,4766.73,2.647,0.378,3.541,0.700079344,45.08541228,1.134,,,,,,,,,,
Load 3,1-Hold,4785.73,2.647,0.378,3.44,0.700079344,43.79944034,1.134,,,,,,,,,,
Load 3,1-Hold,4804.73,2.647,0.378,3.541,0.700079344,45.08541228,1.134,,,,,,,,,,
Load 3,1-Hold,4823.73,2.647,0.378,3.44,0.700079344,43.79944034,1.134,,,,,,,,,,
Load 3,1-Hold,4842.73,2.647,0.378,3.34,0.700079344,42.52620079,1.134,,,,,,,,,,
Load 3,1-Hold,4861.73,2.647,0.378,3.44,0.700079344,43.79944034,1.134,,,,,,,,,,
Load 3,1-Hold,4880.73,2.647,0.378,3.44,0.700079344,43.79944034,1.134,,,,,,,,,,
Load 3,1-Hold,4899.73,2.647,0.378,3.44,0.700079344,43.79944034,1.134,,,,,,,,,,
Load 3,1-Hold,4918.73,2.647,0.378,3.44,0.700079344,43.79944034,1.134,,,,,,,,,,
Load 3,1-Hold,4937.73,2.647,0.378,3.34,0.700079344,42.52620079,1.134,,,,,,,,,,
Load 3,1-Hold,4956.73,2.647,0.378,3.44,0.700079344,43.79944034,1.134,,,,,,,,,,
Load 3,1-Hold,4975.73,2.647,0.378,3.038,0.700079344,38.68101737,1.134,,,,,,,,,,
Load 3,1-Hold,4994.73,2.647,0.378,3.038,0.700079344,38.68101737,1.134,,,,,,,,,,
Load 3,1-Hold,5013.73,2.647,0.378,2.938,0.700079344,37.40777782,1.134,,,,,,,,,,
Load 3,1-Hold,5032.73,2.647,0.378,2.737,0.700079344,34.84856634,1.134,,,,,,,,,,
Load 3,1-Hold,5051.73,2.647,0.378,3.139,0.700079344,39.96698931,1.134,,,,,,,,,,
Load 3,1-Hold,5070.73,2.647,0.378,2.838,0.700079344,36.13453828,1.134,,,,,,,,,,
Load 3,1-Hold,5089.73,2.647,0.378,2.737,0.700079344,34.84856634,1.134,,,,,,,,,,
Load 3,1-Hold,5108.73,2.647,0.378,2.938,0.700079344,37.40777782,1.134,,,,,,,,,,
Load 3,1-Hold,5127.73,2.647,0.378,2.737,0.700079344,34.84856634,1.134,,,,,,,,,,
Load 3,1-Hold,5146.73,2.647,0.378,2.737,0.700079344,34.84856634,1.134,,,,,,,,,,
Load 3,1-Hold,5165.73,2.647,0.378,2.637,0.700079344,33.57532679,1.134,,,,,,,,,,
Load 3,1-Hold,5184.73,2.647,0.378,2.737,0.700079344,34.84856634,1.134,,,,,,,,,,
Load 3,1-Hold,5203.73,2.647,0.378,2.838,0.700079344,36.13453828,1.134,,,,,,,,,,
Load 3,1-Hold,5222.73,2.647,0.378,2.637,0.700079344,33.57532679,1.134,,,,,,,,,,
Load 3,1-Hold,5241.73,2.647,0.378,2.637,0.700079344,33.57532679,1.134,,,,,,,,,,
Load 3,1-Hold,5260.73,2.647,0.378,2.637,0.700079344,33.57532679,1.134,,,,,,,,,,
Load 3,1-Hold,5279.73,2.647,0.378,2.637,0.700079344,33.57532679,1.134,,,,,,,,,,
Load 3,1-Hold,5298.73,2.647,0.378,2.637,0.700079344,33.57532679,1.134,,,,,,,,,,
Load 3,1-Hold,5317.73,2.647,0.378,2.637,0.700079344,33.57532679,1.134,,,,,,,,,,
Load 3,1-Hold,5336.73,2.647,0.378,2.637,0.700079344,33.57532679,1.134,,,,,,,,,,
Load 3,1-Hold,5355.73,2.647,0.378,2.637,0.700079344,33.57532679,1.134,,,,,,,,,,
Load 3,1-Hold,5374.73,2.647,0.378,2.637,0.700079344,33.57532679,1.134,,,,,,,,,,
Load 3,1-Hold,5393.73,2.647,0.378,2.637,0.700079344,33.57532679,1.134,,,,,,,,,,
Load 3,1-Hold,5412.73,2.647,0.378,2.637,0.700079344,33.57532679,1.134,,,,,,,,,,
Load 3,1-Hold,5431.73,2.647,0.378,2.637,0.700079344,33.57532679,1.134,,,,,,,,,,
Load 3,1-Hold,5450.73,2.647,0.378,2.336,0.700079344,29.74287577,1.134,,,,,,,,,,
Load 3,1-Hold,5469.73,2.647,0.378,2.336,0.700079344,29.74287577,1.134,,,,,,,,,,
Load 3,1-Hold,5488.73,2.647,0.378,2.235,0.700079344,28.45690382,1.134,,,,,,,,,,
Load 3,1-Hold,5507.73,2.647,0.378,2.336,0.700079344,29.74287577,1.134,,,,,,,,,,
Load 3,1-Hold,5526.73,2.647,0.378,2.034,0.700079344,25.89769234,1.134,,,,,,,,,,
Load 3,1-Hold,5545.73,2.647,0.378,2.135,0.700079344,27.18366428,1.134,,,,,,,,,,
Load 3,1-Hold,5564.73,2.647,0.378,2.235,0.700079344,28.45690382,1.134,,,,,,,,,,
Load 3,1-Hold,5583.73,2.647,0.378,1.934,0.700079344,24.6244528,1.134,,,,,,,,,,
Load 3,1-Hold,5602.73,2.647,0.378,2.336,0.700079344,29.74287577,1.134,,,,,,,,,,
Load 3,1-Hold,5621.73,2.647,0.378,2.135,0.700079344,27.18366428,1.134,,,,,,,,,,
Load 4,1-Compress,5640.72,2.643,0.004,2.838,0.699021423,36.13453828,1.138,,,,,,,,,,
Load 4,1-Compress,5659.72,2.624,0.023,5.448,0.693996297,69.3660904,1.157,,,,,,,,,,
Load 4,1-Compress,5678.72,2.605,0.042,8.059,0.688971172,102.6103749,1.176,,,,,,,,,,
Load 4,1-Compress,5697.72,2.586,0.061,10.77,0.683946046,137.127899,1.195,,,,,,,,,,
Load 4,1-Compress,5716.72,2.568,0.079,12.678,0.679185401,161.4213095,1.213,,,,,,,,,,
Load 4,1-Compress,5735.72,2.549,0.098,16.293,0.674160275,207.448919,1.232,,,,,,,,,,
Load 4,1-Compress,5754.72,2.529,0.118,18.301,0.668870669,233.0155691,1.252,,,,,,,,,,
Load 4,1-Compress,5773.72,2.51,0.137,20.008,0.663845544,254.7497681,1.271,,,,,,,,,,
Load 4,1-Compress,5792.72,2.491,0.156,21.213,0.658820418,270.0923046,1.29,,,,,,,,,,
Load 4,1-Compress,5811.72,2.473,0.174,22.016,0.654059773,280.3164182,1.308,,,,,,,,,,
Load 4,1-Compress,5830.72,2.454,0.193,22.719,0.649034647,289.2672922,1.327,,,,,,,,,,
Load 4,1-Compress,5849.72,2.434,0.213,23.522,0.643745041,299.4914057,1.347,,,,,,,,,,
Load 4,1-Compress,5868.72,2.415,0.232,23.723,0.638719915,302.0506172,1.366,,,,,,,,,,
Load 4,1-Compress,5887.72,2.396,0.251,24.225,0.63369479,308.4422797,1.385,,,,,,,,,,
Load 4,1-Compress,5906.72,2.378,0.269,24.426,0.628934144,311.0014912,1.403,,,,,,,,,,
Load 4,1-Compress,5925.72,2.359,0.288,24.326,0.623909019,309.7282517,1.422,,,,,,,,,,
Load 4,1-Compress,5944.72,2.34,0.307,24.426,0.618883893,311.0014912,1.441,,,,,,,,,,
Load 4,1-Compress,5963.72,2.32,0.327,25.129,0.613594287,319.9523652,1.461,,,,,,,,,,
Load 4,1-Compress,5982.72,2.302,0.345,25.129,0.608833642,319.9523652,1.479,,,,,,,,,,
Load 4,1-Compress,6001.72,2.283,0.364,25.229,0.603808516,321.2256047,1.498,,,,,,,,,,
Load 4,1-Hold,6019.97,2.269,0.378,24.326,0.600105792,309.7282517,1.512,,,,,,,,,,
Load 4,1-Hold,6038.97,2.269,0.378,20.008,0.600105792,254.7497681,1.512,,,,,,,,,,
Load 4,1-Hold,6057.97,2.269,0.378,16.494,0.600105792,210.0081305,1.512,,,,,,,,,,
Load 4,1-Hold,6076.97,2.269,0.378,14.787,0.600105792,188.2739315,1.512,,,,,,,,,,
Load 4,1-Hold,6095.97,2.269,0.378,13.08,0.600105792,166.5397325,1.512,,,,,,,,,,
Load 4,1-Hold,6114.97,2.269,0.378,12.276,0.600105792,156.3028865,1.512,,,,,,,,,,
Load 4,1-Hold,6133.97,2.269,0.378,11.071,0.600105792,140.96035,1.512,,,,,,,,,,
Load 4,1-Hold,6152.97,2.269,0.378,10.67,0.600105792,135.8546594,1.512,,,,,,,,,,
Load 4,1-Hold,6171.97,2.269,0.378,10.067,0.600105792,128.177025,1.512,,,,,,,,,,
Load 4,1-Hold,6190.97,2.269,0.378,9.364,0.600105792,119.226151,1.512,,,,,,,,,,
Load 4,1-Hold,6209.97,2.269,0.378,8.561,0.600105792,109.0020374,1.512,,,,,,,,,,
Load 4,1-Hold,6228.97,2.269,0.378,8.762,0.600105792,111.5612489,1.512,,,,,,,,,,
Load 4,1-Hold,6247.97,2.269,0.378,8.26,0.600105792,105.1695864,1.512,,,,,,,,,,
Load 4,1-Hold,6266.97,2.269,0.378,8.26,0.600105792,105.1695864,1.512,,,,,,,,,,
Load 4,1-Hold,6285.97,2.269,0.378,7.758,0.600105792,98.77792388,1.512,,,,,,,,,,
Load 4,1-Hold,6304.97,2.269,0.378,7.457,0.600105792,94.94547285,1.512,,,,,,,,,,
Load 4,1-Hold,6323.97,2.269,0.378,7.256,0.600105792,92.38626137,1.512,,,,,,,,,,
Load 4,1-Hold,6342.97,2.269,0.378,7.356,0.600105792,93.65950091,1.512,,,,,,,,,,
Load 4,1-Hold,6361.97,2.269,0.378,6.754,0.600105792,85.99459885,1.512,,,,,,,,,,
Load 4,1-Hold,6380.97,2.269,0.378,7.055,0.600105792,89.82704988,1.512,,,,,,,,,,
Load 4,1-Hold,6399.97,2.269,0.378,6.754,0.600105792,85.99459885,1.512,,,,,,,,,,
Load 4,1-Hold,6418.97,2.269,0.378,6.653,0.600105792,84.70862691,1.512,,,,,,,,,,
Load 4,1-Hold,6437.97,2.269,0.378,6.452,0.600105792,82.14941543,1.512,,,,,,,,,,
Load 4,1-Hold,6456.97,2.269,0.378,6.051,0.600105792,77.04372485,1.512,,,,,,,,,,
Load 4,1-Hold,6475.97,2.269,0.378,6.051,0.600105792,77.04372485,1.512,,,,,,,,,,
Load 4,1-Hold,6494.97,2.269,0.378,6.051,0.600105792,77.04372485,1.512,,,,,,,,,,
Load 4,1-Hold,6513.97,2.269,0.378,5.85,0.600105792,74.48451337,1.512,,,,,,,,,,
Load 4,1-Hold,6532.97,2.269,0.378,5.85,0.600105792,74.48451337,1.512,,,,,,,,,,
Load 4,1-Hold,6551.97,2.269,0.378,5.85,0.600105792,74.48451337,1.512,,,,,,,,,,
Load 4,1-Hold,6570.97,2.269,0.378,5.649,0.600105792,71.92530188,1.512,,,,,,,,,,
Load 4,1-Hold,6589.97,2.269,0.378,5.549,0.600105792,70.65206234,1.512,,,,,,,,,,
Load 4,1-Hold,6608.97,2.269,0.378,5.147,0.600105792,65.53363937,1.512,,,,,,,,,,
Load 4,1-Hold,6627.97,2.269,0.378,5.248,0.600105792,66.81961131,1.512,,,,,,,,,,
Load 4,1-Hold,6646.97,2.269,0.378,5.448,0.600105792,69.3660904,1.512,,,,,,,,,,
Load 4,1-Hold,6665.97,2.269,0.378,5.147,0.600105792,65.53363937,1.512,,,,,,,,,,
Load 4,1-Hold,6684.97,2.269,0.378,5.348,0.600105792,68.09285085,1.512,,,,,,,,,,
Load 4,1-Hold,6703.97,2.269,0.378,5.248,0.600105792,66.81961131,1.512,,,,,,,,,,
Load 4,1-Hold,6722.97,2.269,0.378,5.549,0.600105792,70.65206234,1.512,,,,,,,,,,
Load 4,1-Hold,6741.97,2.269,0.378,5.348,0.600105792,68.09285085,1.512,,,,,,,,,,
Load 4,1-Hold,6760.97,2.269,0.378,5.448,0.600105792,69.3660904,1.512,,,,,,,,,,
Load 4,1-Hold,6779.97,2.269,0.378,5.549,0.600105792,70.65206234,1.512,,,,,,,,,,
Load 4,1-Hold,6798.97,2.269,0.378,5.248,0.600105792,66.81961131,1.512,,,,,,,,,,
Load 4,1-Hold,6817.97,2.269,0.378,5.147,0.600105792,65.53363937,1.512,,,,,,,,,,
Load 4,1-Hold,6836.97,2.269,0.378,5.047,0.600105792,64.26039982,1.512,,,,,,,,,,
Load 4,1-Hold,6855.97,2.269,0.378,5.047,0.600105792,64.26039982,1.512,,,,,,,,,,
Load 4,1-Hold,6874.97,2.269,0.378,5.047,0.600105792,64.26039982,1.512,,,,,,,,,,
Load 4,1-Hold,6893.97,2.269,0.378,5.047,0.600105792,64.26039982,1.512,,,,,,,,,,
Load 4,1-Hold,6912.97,2.269,0.378,5.047,0.600105792,64.26039982,1.512,,,,,,,,,,
Load 4,1-Hold,6931.97,2.269,0.378,5.047,0.600105792,64.26039982,1.512,,,,,,,,,,
Load 4,1-Hold,6950.97,2.269,0.378,4.846,0.600105792,61.70118834,1.512,,,,,,,,,,
Load 4,1-Hold,6969.97,2.269,0.378,5.047,0.600105792,64.26039982,1.512,,,,,,,,,,
Load 4,1-Hold,6988.97,2.269,0.378,4.745,0.600105792,60.4152164,1.512,,,,,,,,,,
Load 4,1-Hold,7007.97,2.269,0.378,4.846,0.600105792,61.70118834,1.512,,,,,,,,,,
Load 4,1-Hold,7026.97,2.269,0.378,5.047,0.600105792,64.26039982,1.512,,,,,,,,,,
Load 4,1-Hold,7045.97,2.269,0.378,4.645,0.600105792,59.14197685,1.512,,,,,,,,,,
Load 4,1-Hold,7064.97,2.269,0.378,4.946,0.600105792,62.97442788,1.512,,,,,,,,,,
Load 4,1-Hold,7083.97,2.269,0.378,4.846,0.600105792,61.70118834,1.512,,,,,,,,,,
Load 4,1-Hold,7102.97,2.269,0.378,4.745,0.600105792,60.4152164,1.512,,,,,,,,,,
Load 4,1-Hold,7121.97,2.269,0.378,5.047,0.600105792,64.26039982,1.512,,,,,,,,,,
Load 4,1-Hold,7140.97,2.269,0.378,4.444,0.600105792,56.58276537,1.512,,,,,,,,,,
Load 4,1-Hold,7159.97,2.269,0.378,4.545,0.600105792,57.86873731,1.512,,,,,,,,,,
Load 4,1-Hold,7178.97,2.269,0.378,4.243,0.600105792,54.02355388,1.512,,,,,,,,,,
Load 4,1-Hold,7197.97,2.269,0.378,4.344,0.600105792,55.30952582,1.512,,,,,,,,,,
Load 4,1-Hold,7216.97,2.269,0.378,4.344,0.600105792,55.30952582,1.512,,,,,,,,,,
Load 4,1-Hold,7235.97,2.269,0.378,4.243,0.600105792,54.02355388,1.512,,,,,,,,,,
Load 4,1-Hold,7254.97,2.269,0.378,4.243,0.600105792,54.02355388,1.512,,,,,,,,,,
Load 4,1-Hold,7273.97,2.269,0.378,4.243,0.600105792,54.02355388,1.512,,,,,,,,,,
Load 4,1-Hold,7292.97,2.269,0.378,4.344,0.600105792,55.30952582,1.512,,,,,,,,,,
Load 4,1-Hold,7311.97,2.269,0.378,4.243,0.600105792,54.02355388,1.512,,,,,,,,,,
Load 4,1-Hold,7330.97,2.269,0.378,4.243,0.600105792,54.02355388,1.512,,,,,,,,,,
Load 4,1-Hold,7349.97,2.269,0.378,4.243,0.600105792,54.02355388,1.512,,,,,,,,,,
Load 4,1-Hold,7368.97,2.269,0.378,4.243,0.600105792,54.02355388,1.512,,,,,,,,,,
Load 4,1-Hold,7387.97,2.269,0.378,4.243,0.600105792,54.02355388,1.512,,,,,,,,,,
Load 4,1-Hold,7406.97,2.269,0.378,4.243,0.600105792,54.02355388,1.512,,,,,,,,,,
Load 4,1-Hold,7425.97,2.269,0.378,4.243,0.600105792,54.02355388,1.512,,,,,,,,,,
Load 4,1-Hold,7444.97,2.269,0.378,4.143,0.600105792,52.75031434,1.512,,,,,,,,,,
Load 4,1-Hold,7463.97,2.269,0.378,4.043,0.600105792,51.47707479,1.512,,,,,,,,,,
Load 4,1-Hold,7482.97,2.269,0.378,4.243,0.600105792,54.02355388,1.512,,,,,,,,,,
Load 4,1-Hold,7501.97,2.269,0.378,3.942,0.600105792,50.19110285,1.512,,,,,,,,,,
Load 5,1-Compress,7520.96,2.264,0.005,5.047,0.598783391,64.26039982,1.517,,,,,,,,,,
Load 5,1-Compress,7539.96,2.245,0.024,7.457,0.593758265,94.94547285,1.536,,,,,,,,,,
Load 5,1-Compress,7558.96,2.226,0.043,10.871,0.588733139,138.4138709,1.555,,,,,,,,,,
Load 5,1-Compress,7577.96,2.207,0.062,13.883,0.583708014,176.763846,1.574,,,,,,,,,,
Load 5,1-Compress,7596.96,2.188,0.081,17.096,0.578682888,217.6730326,1.593,,,,,,,,,,
Load 5,1-Compress,7615.96,2.17,0.099,20.008,0.573922243,254.7497681,1.611,,,,,,,,,,
Load 5,1-Compress,7634.96,2.151,0.118,21.916,0.568897117,279.0431786,1.63,,,,,,,,,,
Load 5,1-Compress,7653.96,2.131,0.138,25.43,0.563607511,323.7848162,1.65,,,,,,,,,,
Load 5,1-Compress,7672.96,2.112,0.157,27.137,0.558582386,345.5190153,1.669,,,,,,,,,,
Load 5,1-Compress,7691.96,2.094,0.175,28.242,0.55382174,359.5883122,1.687,,,,,,,,,,
Load 5,1-Compress,7710.96,2.074,0.195,29.145,0.548532134,371.0856653,1.707,,,,,,,,,,
Load 5,1-Compress,7729.96,2.055,0.214,29.949,0.543507009,381.3225113,1.726,,,,,,,,,,
Load 5,1-Compress,7748.96,2.036,0.233,29.949,0.538481883,381.3225113,1.745,,,,,,,,,,
Load 5,1-Compress,7767.96,2.017,0.252,29.949,0.533456757,381.3225113,1.764,,,,,,,,,,
Load 5,1-Compress,7786.96,1.999,0.27,29.949,0.528696112,381.3225113,1.782,,,,,,,,,,
Load 5,1-Compress,7805.96,1.98,0.289,29.949,0.523670987,381.3225113,1.801,,,,,,,,,,
Load 5,1-Compress,7824.96,1.96,0.309,30.652,0.518381381,390.2733853,1.821,,,,,,,,,,
Load 5,1-Compress,7843.96,1.941,0.328,30.652,0.513356255,390.2733853,1.84,,,,,,,,,,
Load 5,1-Compress,7862.96,1.922,0.347,30.752,0.508331129,391.5466248,1.859,,,,,,,,,,
Load 5,1-Compress,7881.96,1.904,0.365,30.752,0.503570484,391.5466248,1.877,,,,,,,,,,
Load 5,1-Hold,7900.2,1.891,0.378,29.547,0.50013224,376.2040883,1.89,,,,,,,,,,
Load 5,1-Hold,7919.2,1.891,0.378,24.426,0.50013224,311.0014912,1.89,,,,,,,,,,
Load 5,1-Hold,7938.2,1.891,0.378,21.113,0.50013224,268.8190651,1.89,,,,,,,,,,
Load 5,1-Hold,7957.2,1.891,0.378,18.703,0.50013224,238.1339921,1.89,,,,,,,,,,
Load 5,1-Hold,7976.2,1.891,0.378,16.393,0.50013224,208.7221586,1.89,,,,,,,,,,
Load 5,1-Hold,7995.2,1.891,0.378,15.289,0.50013224,194.665594,1.89,,,,,,,,,,
Load 5,1-Hold,8014.2,1.891,0.378,14.084,0.50013224,179.3230575,1.89,,,,,,,,,,
Load 5,1-Hold,8033.2,1.891,0.378,13.08,0.50013224,166.5397325,1.89,,,,,,,,,,
Load 5,1-Hold,8052.2,1.891,0.378,12.276,0.50013224,156.3028865,1.89,,,,,,,,,,
Load 5,1-Hold,8071.2,1.891,0.378,11.573,0.50013224,147.3520125,1.89,,,,,,,,,,
Load 5,1-Hold,8090.2,1.891,0.378,10.871,0.50013224,138.4138709,1.89,,,,,,,,,,
Load 5,1-Hold,8109.2,1.891,0.378,10.67,0.50013224,135.8546594,1.89,,,,,,,,,,
Load 5,1-Hold,8128.2,1.891,0.378,10.268,0.50013224,130.7362365,1.89,,,,,,,,,,
Load 5,1-Hold,8147.2,1.891,0.378,9.666,0.50013224,123.0713344,1.89,,,,,,,,,,
Load 5,1-Hold,8166.2,1.891,0.378,9.264,0.50013224,117.9529114,1.89,,,,,,,,,,
Load 5,1-Hold,8185.2,1.891,0.378,9.063,0.50013224,115.3936999,1.89,,,,,,,,,,
Load 5,1-Hold,8204.2,1.891,0.378,9.063,0.50013224,115.3936999,1.89,,,,,,,,,,
Load 5,1-Hold,8223.2,1.891,0.378,8.762,0.50013224,111.5612489,1.89,,,,,,,,,,
Load 5,1-Hold,8242.2,1.891,0.378,8.662,0.50013224,110.2880094,1.89,,,,,,,,,,
Load 5,1-Hold,8261.2,1.891,0.378,8.26,0.50013224,105.1695864,1.89,,,,,,,,,,
Load 5,1-Hold,8280.2,1.891,0.378,8.059,0.50013224,102.6103749,1.89,,,,,,,,,,
Load 5,1-Hold,8299.2,1.891,0.378,8.059,0.50013224,102.6103749,1.89,,,,,,,,,,
Load 5,1-Hold,8318.2,1.891,0.378,7.858,0.50013224,100.0511634,1.89,,,,,,,,,,
Load 5,1-Hold,8337.2,1.891,0.378,7.457,0.50013224,94.94547285,1.89,,,,,,,,,,
Load 5,1-Hold,8356.2,1.891,0.378,7.457,0.50013224,94.94547285,1.89,,,,,,,,,,
Load 5,1-Hold,8375.2,1.891,0.378,7.155,0.50013224,91.10028943,1.89,,,,,,,,,,
Load 5,1-Hold,8394.2,1.891,0.378,7.256,0.50013224,92.38626137,1.89,,,,,,,,,,
Load 5,1-Hold,8413.2,1.891,0.378,6.955,0.50013224,88.55381034,1.89,,,,,,,,,,
Load 5,1-Hold,8432.2,1.891,0.378,7.055,0.50013224,89.82704988,1.89,,,,,,,,,,
Load 5,1-Hold,8451.2,1.891,0.378,6.854,0.50013224,87.2678384,1.89,,,,,,,,,,
Load 5,1-Hold,8470.2,1.891,0.378,6.754,0.50013224,85.99459885,1.89,,,,,,,,,,
Load 5,1-Hold,8489.2,1.891,0.378,6.653,0.50013224,84.70862691,1.89,,,,,,,,,,
Load 5,1-Hold,8508.2,1.891,0.378,6.653,0.50013224,84.70862691,1.89,,,,,,,,,,
Load 5,1-Hold,8527.2,1.891,0.378,6.653,0.50013224,84.70862691,1.89,,,,,,,,,,
Load 5,1-Hold,8546.2,1.891,0.378,6.252,0.50013224,79.60293634,1.89,,,,,,,,,,
Load 5,1-Hold,8565.2,1.891,0.378,5.95,0.50013224,75.75775291,1.89,,,,,,,,,,
Load 5,1-Hold,8584.2,1.891,0.378,6.352,0.50013224,80.87617588,1.89,,,,,,,,,,
Load 5,1-Hold,8603.2,1.891,0.378,6.051,0.50013224,77.04372485,1.89,,,,,,,,,,
Load 5,1-Hold,8622.2,1.891,0.378,6.051,0.50013224,77.04372485,1.89,,,,,,,,,,
Load 5,1-Hold,8641.2,1.891,0.378,5.95,0.50013224,75.75775291,1.89,,,,,,,,,,
Load 5,1-Hold,8660.2,1.891,0.378,5.95,0.50013224,75.75775291,1.89,,,,,,,,,,
Load 5,1-Hold,8679.2,1.891,0.378,5.85,0.50013224,74.48451337,1.89,,,,,,,,,,
Load 5,1-Hold,8698.2,1.891,0.378,5.85,0.50013224,74.48451337,1.89,,,,,,,,,,
Load 5,1-Hold,8717.2,1.891,0.378,5.85,0.50013224,74.48451337,1.89,,,,,,,,,,
Load 5,1-Hold,8736.2,1.891,0.378,5.75,0.50013224,73.21127382,1.89,,,,,,,,,,
Load 5,1-Hold,8755.2,1.891,0.378,5.348,0.50013224,68.09285085,1.89,,,,,,,,,,
Load 5,1-Hold,8774.2,1.891,0.378,5.448,0.50013224,69.3660904,1.89,,,,,,,,,,
Load 5,1-Hold,8793.2,1.891,0.378,5.448,0.50013224,69.3660904,1.89,,,,,,,,,,
Load 5,1-Hold,8812.2,1.891,0.378,5.147,0.50013224,65.53363937,1.89,,,,,,,,,,
Load 5,1-Hold,8831.2,1.891,0.378,5.448,0.50013224,69.3660904,1.89,,,,,,,,,,
Load 5,1-Hold,8850.2,1.891,0.378,5.348,0.50013224,68.09285085,1.89,,,,,,,,,,
Load 5,1-Hold,8869.2,1.891,0.378,5.248,0.50013224,66.81961131,1.89,,,,,,,,,,
Load 5,1-Hold,8888.2,1.891,0.378,5.448,0.50013224,69.3660904,1.89,,,,,,,,,,
Load 5,1-Hold,8907.2,1.891,0.378,5.147,0.50013224,65.53363937,1.89,,,,,,,,,,
Load 5,1-Hold,8926.2,1.891,0.378,5.147,0.50013224,65.53363937,1.89,,,,,,,,,,
Load 5,1-Hold,8945.2,1.891,0.378,5.348,0.50013224,68.09285085,1.89,,,,,,,,,,
Load 5,1-Hold,8964.2,1.891,0.378,5.549,0.50013224,70.65206234,1.89,,,,,,,,,,
Load 5,1-Hold,8983.2,1.891,0.378,5.348,0.50013224,68.09285085,1.89,,,,,,,,,,
Load 5,1-Hold,9002.2,1.891,0.378,5.348,0.50013224,68.09285085,1.89,,,,,,,,,,
Load 5,1-Hold,9021.2,1.891,0.378,5.75,0.50013224,73.21127382,1.89,,,,,,,,,,
Load 5,1-Hold,9040.2,1.891,0.378,5.448,0.50013224,69.3660904,1.89,,,,,,,,,,
Load 5,1-Hold,9059.2,1.891,0.378,5.549,0.50013224,70.65206234,1.89,,,,,,,,,,
Load 5,1-Hold,9078.2,1.891,0.378,5.549,0.50013224,70.65206234,1.89,,,,,,,,,,
Load 5,1-Hold,9097.2,1.891,0.378,5.147,0.50013224,65.53363937,1.89,,,,,,,,,,
Load 5,1-Hold,9116.2,1.891,0.378,5.047,0.50013224,64.26039982,1.89,,,,,,,,,,
Load 5,1-Hold,9135.2,1.891,0.378,5.047,0.50013224,64.26039982,1.89,,,,,,,,,,
Load 5,1-Hold,9154.2,1.891,0.378,5.047,0.50013224,64.26039982,1.89,,,,,,,,,,
Load 5,1-Hold,9173.2,1.891,0.378,5.047,0.50013224,64.26039982,1.89,,,,,,,,,,
Load 5,1-Hold,9192.2,1.891,0.378,5.047,0.50013224,64.26039982,1.89,,,,,,,,,,
Load 5,1-Hold,9211.2,1.891,0.378,5.047,0.50013224,64.26039982,1.89,,,,,,,,,,
Load 5,1-Hold,9230.2,1.891,0.378,5.047,0.50013224,64.26039982,1.89,,,,,,,,,,
Load 5,1-Hold,9249.2,1.891,0.378,4.946,0.50013224,62.97442788,1.89,,,,,,,,,,
Load 5,1-Hold,9268.2,1.891,0.378,5.047,0.50013224,64.26039982,1.89,,,,,,,,,,
Load 5,1-Hold,9287.2,1.891,0.378,5.047,0.50013224,64.26039982,1.89,,,,,,,,,,
Load 5,1-Hold,9306.2,1.891,0.378,4.946,0.50013224,62.97442788,1.89,,,,,,,,,,
Load 5,1-Hold,9325.2,1.891,0.378,5.047,0.50013224,64.26039982,1.89,,,,,,,,,,
Load 5,1-Hold,9344.2,1.891,0.378,4.645,0.50013224,59.14197685,1.89,,,,,,,,,,
Load 5,1-Hold,9363.2,1.891,0.378,4.946,0.50013224,62.97442788,1.89,,,,,,,,,,
Load 5,1-Hold,9382.2,1.891,0.378,4.946,0.50013224,62.97442788,1.89,,,,,,,,,,
Load 6,1-Compress,9401.2,1.885,0.006,5.448,0.498545358,69.3660904,1.896,,,,,,,,,,
Load 6,1-Compress,9420.2,1.865,0.026,9.264,0.493255752,117.9529114,1.916,,,,,,,,,,
Load 6,1-Compress,9439.2,1.848,0.043,12.879,0.488759587,163.980521,1.933,,,,,,,,,,
Load 6,1-Compress,9458.2,1.828,0.063,17.096,0.483469981,217.6730326,1.953,,,,,,,,,,
Load 6,1-Compress,9477.2,1.809,0.082,20.108,0.478444856,256.0230077,1.972,,,,,,,,,,
Load 6,1-Compress,9496.2,1.79,0.101,24.024,0.47341973,305.8830682,1.991,,,,,,,,,,
Load 6,1-Compress,9515.2,1.771,0.12,27.438,0.468394605,349.3514663,2.01,,,,,,,,,,
Load 6,1-Compress,9534.2,1.752,0.139,30.451,0.463369479,387.7141738,2.029,,,,,,,,,,
Load 6,1-Compress,9553.2,1.733,0.158,32.258,0.458344353,410.7216123,2.048,,,,,,,,,,
Load 6,1-Compress,9572.2,1.714,0.177,34.769,0.453319228,442.6926573,2.067,,,,,,,,,,
Load 6,1-Compress,9591.2,1.695,0.196,35.572,0.448294102,452.9167709,2.086,,,,,,,,,,
Load 6,1-Compress,9610.2,1.676,0.215,36.676,0.443268976,466.9733354,2.105,,,,,,,,,,
Load 6,1-Compress,9629.2,1.657,0.234,37.379,0.438243851,475.9242094,2.124,,,,,,,,,,
Load 6,1-Compress,9648.2,1.638,0.253,36.877,0.433218725,469.5325469,2.143,,,,,,,,,,
Load 6,1-Compress,9667.2,1.619,0.272,37.881,0.4281936,482.3158719,2.162,,,,,,,,,,
Load 6,1-Compress,9686.2,1.601,0.29,37.178,0.423432954,473.3649979,2.18,,,,,,,,,,
Load 6,1-Compress,9705.2,1.582,0.309,37.68,0.418407829,479.7566605,2.199,,,,,,,,,,
Load 6,1-Compress,9724.2,1.562,0.329,38.785,0.413118223,493.8259574,2.219,,,,,,,,,,
Load 6,1-Compress,9743.2,1.543,0.348,38.383,0.408093097,488.7075345,2.238,,,,,,,,,,
Load 6,1-Compress,9762.2,1.524,0.367,38.986,0.403067971,496.3851689,2.257,,,,,,,,,,
Load 6,1-Hold,9780.44,1.513,0.378,36.978,0.400158688,470.8185189,2.268,,,,,,,,,,
Load 6,1-Hold,9799.44,1.513,0.378,31.555,0.400158688,401.7707383,2.268,,,,,,,,,,
Load 6,1-Hold,9818.44,1.513,0.378,27.539,0.400158688,350.6374382,2.268,,,,,,,,,,
Load 6,1-Hold,9837.44,1.513,0.378,24.527,0.400158688,312.2874631,2.268,,,,,,,,,,
Load 6,1-Hold,9856.44,1.513,0.378,22.619,0.400158688,287.9940526,2.268,,,,,,,,,,
Load 6,1-Hold,9875.44,1.513,0.378,20.711,0.400158688,263.7006421,2.268,,,,,,,,,,
Load 6,1-Hold,9894.44,1.513,0.378,19.506,0.400158688,248.3581056,2.268,,,,,,,,,,
Load 6,1-Hold,9913.44,1.513,0.378,18.1,0.400158688,230.4563576,2.268,,,,,,,,,,
Load 6,1-Hold,9932.44,1.513,0.378,16.996,0.400158688,216.399793,2.268,,,,,,,,,,
Load 6,1-Hold,9951.44,1.513,0.378,16.293,0.400158688,207.448919,2.268,,,,,,,,,,
Load 6,1-Hold,9970.44,1.513,0.378,15.389,0.400158688,195.9388335,2.268,,,,,,,,,,
Load 6,1-Hold,9989.44,1.513,0.378,14.686,0.400158688,186.9879595,2.268,,,,,,,,,,
Load 6,1-Hold,10008.44,1.513,0.378,14.084,0.400158688,179.3230575,2.268,,,,,,,,,,
Load 6,1-Hold,10027.44,1.513,0.378,13.481,0.400158688,171.645423,2.268,,,,,,,,,,
Load 6,1-Hold,10046.44,1.513,0.378,13.08,0.400158688,166.5397325,2.268,,,,,,,,,,
Load 6,1-Hold,10065.44,1.513,0.378,12.578,0.400158688,160.1480699,2.268,,,,,,,,,,
Load 6,1-Hold,10084.44,1.513,0.378,12.276,0.400158688,156.3028865,2.268,,,,,,,,,,
Load 6,1-Hold,10103.44,1.513,0.378,12.276,0.400158688,156.3028865,2.268,,,,,,,,,,
Load 6,1-Hold,10122.44,1.513,0.378,11.573,0.400158688,147.3520125,2.268,,,,,,,,,,
Load 6,1-Hold,10141.44,1.513,0.378,11.473,0.400158688,146.078773,2.268,,,,,,,,,,
Load 6,1-Hold,10160.44,1.513,0.378,11.071,0.400158688,140.96035,2.268,,,,,,,,,,
Load 6,1-Hold,10179.44,1.513,0.378,10.971,0.400158688,139.6871105,2.268,,,,,,,,,,
Load 6,1-Hold,10198.44,1.513,0.378,10.67,0.400158688,135.8546594,2.268,,,,,,,,,,
Load 6,1-Hold,10217.44,1.513,0.378,10.368,0.400158688,132.009476,2.268,,,,,,,,,,
Load 6,1-Hold,10236.44,1.513,0.378,10.168,0.400158688,129.4629969,2.268,,,,,,,,,,
Load 6,1-Hold,10255.44,1.513,0.378,9.967,0.400158688,126.9037854,2.268,,,,,,,,,,
Load 6,1-Hold,10274.44,1.513,0.378,9.866,0.400158688,125.6178135,2.268,,,,,,,,,,
Load 6,1-Hold,10293.44,1.513,0.378,9.264,0.400158688,117.9529114,2.268,,,,,,,,,,
Load 6,1-Hold,10312.44,1.513,0.378,9.264,0.400158688,117.9529114,2.268,,,,,,,,,,
Load 6,1-Hold,10331.44,1.513,0.378,9.063,0.400158688,115.3936999,2.268,,,,,,,,,,
Load 6,1-Hold,10350.44,1.513,0.378,9.063,0.400158688,115.3936999,2.268,,,,,,,,,,
Load 6,1-Hold,10369.44,1.513,0.378,9.063,0.400158688,115.3936999,2.268,,,,,,,,,,
Load 6,1-Hold,10388.44,1.513,0.378,9.063,0.400158688,115.3936999,2.268,,,,,,,,,,
Load 6,1-Hold,10407.44,1.513,0.378,9.063,0.400158688,115.3936999,2.268,,,,,,,,,,
Load 6,1-Hold,10426.44,1.513,0.378,8.662,0.400158688,110.2880094,2.268,,,,,,,,,,
Load 6,1-Hold,10445.44,1.513,0.378,8.862,0.400158688,112.8344885,2.268,,,,,,,,,,
Load 6,1-Hold,10464.44,1.513,0.378,8.862,0.400158688,112.8344885,2.268,,,,,,,,,,
Load 6,1-Hold,10483.44,1.513,0.378,8.26,0.400158688,105.1695864,2.268,,,,,,,,,,
Load 6,1-Hold,10502.44,1.513,0.378,8.26,0.400158688,105.1695864,2.268,,,,,,,,,,
Load 6,1-Hold,10521.44,1.513,0.378,8.159,0.400158688,103.8836145,2.268,,,,,,,,,,
Load 6,1-Hold,10540.44,1.513,0.378,8.059,0.400158688,102.6103749,2.268,,,,,,,,,,
Load 6,1-Hold,10559.44,1.513,0.378,8.26,0.400158688,105.1695864,2.268,,,,,,,,,,
Load 6,1-Hold,10578.44,1.513,0.378,7.959,0.400158688,101.3371354,2.268,,,,,,,,,,
Load 6,1-Hold,10597.44,1.513,0.378,8.059,0.400158688,102.6103749,2.268,,,,,,,,,,
Load 6,1-Hold,10616.44,1.513,0.378,7.457,0.400158688,94.94547285,2.268,,,,,,,,,,
Load 6,1-Hold,10635.44,1.513,0.378,7.457,0.400158688,94.94547285,2.268,,,,,,,,,,
Load 6,1-Hold,10654.44,1.513,0.378,7.457,0.400158688,94.94547285,2.268,,,,,,,,,,
Load 6,1-Hold,10673.44,1.513,0.378,7.457,0.400158688,94.94547285,2.268,,,,,,,,,,
Load 6,1-Hold,10692.44,1.513,0.378,7.457,0.400158688,94.94547285,2.268,,,,,,,,,,
Load 6,1-Hold,10711.44,1.513,0.378,7.457,0.400158688,94.94547285,2.268,,,,,,,,,,
Load 6,1-Hold,10730.44,1.513,0.378,7.055,0.400158688,89.82704988,2.268,,,,,,,,,,
Load 6,1-Hold,10749.44,1.513,0.378,7.356,0.400158688,93.65950091,2.268,,,,,,,,,,
Load 6,1-Hold,10768.44,1.513,0.378,7.356,0.400158688,93.65950091,2.268,,,,,,,,,,
Load 6,1-Hold,10787.44,1.513,0.378,7.256,0.400158688,92.38626137,2.268,,,,,,,,,,
Load 6,1-Hold,10806.44,1.513,0.378,7.155,0.400158688,91.10028943,2.268,,,,,,,,,,
Load 6,1-Hold,10825.44,1.513,0.378,7.155,0.400158688,91.10028943,2.268,,,,,,,,,,
Load 6,1-Hold,10844.44,1.513,0.378,6.955,0.400158688,88.55381034,2.268,,,,,,,,,,
Load 6,1-Hold,10863.44,1.513,0.378,6.754,0.400158688,85.99459885,2.268,,,,,,,,,,
Load 6,1-Hold,10882.44,1.513,0.378,7.155,0.400158688,91.10028943,2.268,,,,,,,,,,
Load 6,1-Hold,10901.44,1.513,0.378,6.754,0.400158688,85.99459885,2.268,,,,,,,,,,
Load 6,1-Hold,10920.44,1.513,0.378,6.854,0.400158688,87.2678384,2.268,,,,,,,,,,
Load 6,1-Hold,10939.44,1.513,0.378,6.754,0.400158688,85.99459885,2.268,,,,,,,,,,
Load 6,1-Hold,10958.44,1.513,0.378,6.653,0.400158688,84.70862691,2.268,,,,,,,,,,
Load 6,1-Hold,10977.44,1.513,0.378,6.653,0.400158688,84.70862691,2.268,,,,,,,,,,
Load 6,1-Hold,10996.44,1.513,0.378,6.653,0.400158688,84.70862691,2.268,,,,,,,,,,
Load 6,1-Hold,11015.44,1.513,0.378,6.653,0.400158688,84.70862691,2.268,,,,,,,,,,
Load 6,1-Hold,11034.44,1.513,0.378,6.653,0.400158688,84.70862691,2.268,,,,,,,,,,
Load 6,1-Hold,11053.44,1.513,0.378,6.653,0.400158688,84.70862691,2.268,,,,,,,,,,
Load 6,1-Hold,11072.44,1.513,0.378,6.653,0.400158688,84.70862691,2.268,,,,,,,,,,
Load 6,1-Hold,11091.44,1.513,0.378,6.653,0.400158688,84.70862691,2.268,,,,,,,,,,
Load 6,1-Hold,11110.44,1.513,0.378,6.653,0.400158688,84.70862691,2.268,,,,,,,,,,
Load 6,1-Hold,11129.44,1.513,0.378,6.553,0.400158688,83.43538737,2.268,,,,,,,,,,
Load 6,1-Hold,11148.44,1.513,0.378,6.653,0.400158688,84.70862691,2.268,,,,,,,,,,
Load 6,1-Hold,11167.44,1.513,0.378,6.452,0.400158688,82.14941543,2.268,,,,,,,,,,
Load 6,1-Hold,11186.44,1.513,0.378,6.653,0.400158688,84.70862691,2.268,,,,,,,,,,
Load 6,1-Hold,11205.44,1.513,0.378,6.151,0.400158688,78.3169644,2.268,,,,,,,,,,
Load 6,1-Hold,11224.44,1.513,0.378,6.252,0.400158688,79.60293634,2.268,,,,,,,,,,
Load 6,1-Hold,11243.44,1.513,0.378,6.252,0.400158688,79.60293634,2.268,,,,,,,,,,
Load 6,1-Hold,11262.44,1.513,0.378,5.95,0.400158688,75.75775291,2.268,,,,,,,,,,
Load 6,1-Hold,11274.44,1.513,0.378,6.252,0.400158688,79.60293634,2.268,,,,,,,,,,